Workbook

Sheet STATS_Digest
A1: Cumulative time for deployments | B1: =STATS!B1 -> #REF! | D1: Number of events per gear | E1: =STATS!J3 -> AT | F1: =STATS!K3 -> 5 | H1: Data Mass (GB) | I1: =SUM(I2:I8) -> 523.23
A2: Number of Events | B2: =STATS!F1 -> 171 | E2: =STATS!J4 -> BATHY | F2: 5 | H2: ROV_frontCAM
A3: Number of Samples | B3: =STATS!F2 -> 3951 | E3: =STATS!J5 -> CTD | F3: =STATS!K5 -> 13 | H3: ROV_GoPRO | I3: 425
A4: Fuel consumption | E4: =STATS!J6 -> CYANO | F4: =STATS!K6 -> 5 | H4: MAVIC2_Bruno | I4: =67+0.97+3.74+2.8+4.25+1.61+3.4+4.2+1.03+1.67+0.78+2.93+1.43+0.08+0.78+0.84+0.48+0.24 -> 98.23
A5: Area covered | E5: =STATS!J2 -> DR | F5: =STATS!K2 -> 5 | H5: Photos
E6: =STATS!J7 -> DRM | F6: =STATS!K7 -> 11 | H6: Videos
E7: =STATS!J8 -> ICE | F7: =STATS!K8 -> 0 | H7: CTD data
E8: =STATS!J9 -> ITD | F8: =STATS!K9 -> 3 | H8: Incubation data
E9: =STATS!J10 -> NIS | F9: =STATS!K10 -> 42
E10: =STATS!J11 -> RD | F10: =STATS!K11 -> 22
E11: =STATS!J12 -> ROV | F11: =STATS!K12 -> 22
E12: =STATS!J13 -> SCUBA | F12: =STATS!K13 -> 30
E13: =STATS!J14 -> SEAICE | F13: =STATS!K14 -> 2
E14: =STATS!J15 -> ST | F14: =STATS!K15 -> 2
E15: =STATS!J16 -> VV | F15: =STATS!K16 -> 7
F17: =SUM(F1:F15) -> 174

Sheet STATS
A1: Time Deployments | B1: =SUM(C:C) -> #REF! | E1: Number of Events | F1: =COUNTA(Events!B:B) -> 171 | H1: Number of Events per gear | J1: Number of Events per gear
A2: =Events!M2 -> 0.42361111 | B2: =Events!#REF! -> #REF! | C2: =B2-A2 -> #REF! | E2: Number of Samples | F2: =COUNTA(Samples!B:B) -> 3951 | H2: AT | I2: 1 | J2: DR | K2: =COUNTIF(H:H, J2) -> 5
A3: =Events!#REF! -> #REF! | B3: =Events!N2 -> 0.6875 | C3: =B3-A3 -> #REF! | H3: AT | I3: 2 | J3: AT | K3: =COUNTIF(H:H, J3) -> 5
A4: =Events!M3 -> 0.5 | B4: =Events!#REF! -> #REF! | C4: =B4-A4 -> #REF! | H4: AT | I4: 3 | J4: BATHY | K4: =COUNTIF(H:H, J4) -> 0
A5: =Events!#REF! -> #REF! | B5: =Events!N3 -> 0.3125 | C5: =B5-A5 -> #REF! | H5: AT | I5: 4 | J5: CTD | K5: =COUNTIF(H:H, J5) -> 13
A6: =Events!M4 -> 0.47916667 | B6: =Events!#REF! -> #REF! | C6: =B6-A6 -> #REF! | H6: AT | I6: 5 | J6: CYANO | K6: =COUNTIF(H:H, J6) -> 5
A7: =Events!#REF! -> #REF! | B7: =Events!N4 -> 0.70833333 | C7: =B7-A7 -> #REF! | H7: CTD | I7: 1 | J7: DRM | K7: =COUNTIF(H:H, J7) -> 11
A8: =Events!M5 -> 0.54166667 | B8: =Events!#REF! -> #REF! | C8: =B8-A8 -> #REF! | H8: CTD | I8: 2 | J8: ICE | K8: =COUNTIF(H:H, J8) -> 0
A9: =Events!#REF! -> #REF! | B9: =Events!N5 -> 0.35416667 | C9: =B9-A9 -> #REF! | H9: CTD | I9: 3 | J9: ITD | K9: =COUNTIF(H:H, J9) -> 3
A10: =Events!M6 -> 0.77083333 | B10: =Events!#REF! -> #REF! | C10: =B10-A10 -> #REF! | H10: CTD | I10: 4 | J10: NIS | K10: =COUNTIF(H:H, J10) -> 42
A11: =Events!#REF! -> #REF! | B11: =Events!N6 -> 0.39583333 | C11: =B11-A11 -> #REF! | H11: CTD | I11: 5 | J11: RD | K11: =COUNTIF(H:H, J11) -> 22
A12: =Events!M7 -> 0 | B12: =Events!N7 -> 0 | C12: =B12-A12 -> 0 | H12: CTD | I12: 6 | J12: ROV | K12: =COUNTIF(H:H, J12) -> 22
A13: =Events!M8 -> 0 | B13: =Events!N8 -> 0 | C13: =B13-A13 -> 0 | H13: CTD | I13: 7 | J13: SCUBA | K13: =COUNTIF(H:H, J13) -> 30
A14: =Events!M9 -> 0 | B14: =Events!N9 -> 0 | C14: =B14-A14 -> 0 | H14: CTD | I14: 8 | J14: SEAICE | K14: =COUNTIF(H:H, J14) -> 2
A15: =Events!M10 -> 0 | B15: =Events!N10 -> 0 | C15: =B15-A15 -> 0 | H15: CTD | I15: 9 | J15: ST | K15: =COUNTIF(H:H, J15) -> 2
A16: =Events!M11 -> 0.75 | B16: =Events!N11 -> 0.77083333 | C16: =B16-A16 -> 0.020833333 | H16: CTD | I16: 10 | J16: VV | K16: =COUNTIF(H:H, J16) -> 7
A17: =Events!M12 -> 0.60625 | B17: =Events!N12 -> 0.625 | C17: =B17-A17 -> 0.01875 | H17: CTD | I17: 11 | J17: ZZ | K17: =COUNTIF(H:H, J17) -> 1
A18: =Events!M13 -> 0.42708333 | B18: =Events!N13 -> 0.44791667 | C18: =B18-A18 -> 0.020833333 | H18: CTD | I18: 13
A19: =Events!M14 -> 0.60138889 | B19: =Events!N14 -> 0.62847222 | C19: =B19-A19 -> 0.027083333 | H19: CTD | I19: 14
A20: =Events!M15 -> 0.35069444 | B20: =Events!N15 -> 0.375 | C20: =B20-A20 -> 0.024305556 | H20: CYANO | I20: 1
A21: =Events!M16 -> 0.43055556 | B21: =Events!N16 -> 0.4375 | C21: =B21-A21 -> 0.0069444444 | H21: CYANO | I21: 2
A22: =Events!M17 -> 0.47152778 | B22: =Events!N17 -> 0.5 | C22: =B22-A22 -> 0.028472222 | H22: CYANO | I22: 3
A23: =Events!M18 -> 0.36944444 | B23: =Events!N18 -> 0.37083333 | C23: =B23-A23 -> 0.0013888889 | H23: CYANO | I23: 4
A24: =Events!M19 -> 0.49444444 | B24: =Events!N19 -> 0.49652778 | C24: =B24-A24 -> 0.0020833333 | H24: CYANO | I24: 5
A25: =Events!M20 -> 0.6875 | B25: =Events!N20 -> 0.70138889 | C25: =B25-A25 -> 0.013888889 | H25: DR | I25: 1
A26: =Events!M21 -> 0.4625 | B26: =Events!N21 -> 0.49305556 | C26: =B26-A26 -> 0.030555556 | H26: DR | I26: 2
A27: =Events!M22 -> 0.46527778 | B27: =Events!N22 -> 0.47222222 | C27: =B27-A27 -> 0.0069444444 | H27: DR | I27: 3
A28: =Events!M23 -> 0.78125 | B28: =Events!N23 -> 0.79166667 | C28: =B28-A28 -> 0.010416667 | H28: DR | I28: 4
A29: =Events!M24 -> 0.75486111 | B29: =Events!N24 -> 0.76875 | C29: =B29-A29 -> 0.013888889 | H29: DR | I29: 5
... A101: =Events!M96 -> 0.60416667 | B101: =Events!N96 -> 0.625 | C101: =B101-A101 -> 0.020833333 | H101: RD | I101: 16
A102: =Events!#REF! -> #REF! | B102: =Events!#REF! -> #REF! | C102: =B102-A102 -> #REF! | H102: RD | I102: 17
A103: =Events!M97 -> 0.60416667 | B103: =Events!N97 -> 0.61805556 | C103: =B103-A103 -> 0.013888889 | H103: RD | I103: 18
A104: =Events!M98 -> 0.36111111 | B104: =Events!N98 -> 0.375 | C104: =B104-A104 -> 0.013888889 | H104: RD | I104: 18
A105: =Events!M99 -> 0.6875 | B105: =Events!N99 -> 0.70833333 | C105: =B105-A105 -> 0.020833333 | H105: RD | I105: 19
A106: =Events!M100 -> 0.625 | B106: =Events!N100 -> 0.63888889 | C106: =B106-A106 -> 0.013888889 | H106: RD | I106: 20
A107: =Events!M101 -> 0.75 | B107: =Events!N101 -> 0.76388889 | C107: =B107-A107 -> 0.013888889 | H107: RD | I107: 21
A108: =Events!M102 -> 0.72916667 | B108: =Events!N102 -> 0.73958333 | C108: =B108-A108 -> 0.010416667 | H108: ROV | I108: 1
A109: =Events!M103 -> 0.45833333 | B109: =Events!N103 -> 0.47222222 | C109: =B109-A109 -> 0.013888889 | H109: ROV | I109: 2
A110: =Events!M104 -> 0.60416667 | B110: =Events!N104 -> 0.61805556 | C110: =B110-A110 -> 0.013888889 | H110: ROV | I110: 3
A111: =Events!M105 -> 0.4375 | B111: =Events!N105 -> 0.45138889 | C111: =B111-A111 -> 0.013888889 | H111: ROV | I111: 4
...

Sheet Events
A1: parentEventID | B1: eventID | C1: eventDate_start | D1: eventDate_end | E1: Collector1 | F1: Collector2 | G1: Collector3 | H1: Collector4 | I1: collector1orcid | J1: collector2orcid | K1: collector3orcid | L1: collector4orcid | M1: Time start (UTC-3) | N1: Time end (UTC-3) | O1: Time start (UTC) | P1: Time end (UTC) | Q1: Latitude start (degree) | R1: Latitude start (decimal minutes) | S1: Longitude start (degree) | T1: Longitude start (decimal minutes) | U1: Latitude end (degree) | V1: Latitude end (decimal minutes) | W1: Longitude end (degree) | X1: Longitude end (decimal minutes) | Y1: Latitude start | Z1: Longitude start | AA1: Latitude end | AB1: Longitude end | AC1: Station Name | AD1: Minimum depth (m) | AE1: Maximum depth(m) | AF1: Max Altitude (m) | AG1: Bottom Depth (m) | AH1: Habitat | AI1: Sampling protocol | AJ1: Gear Type | AK1: Event Remarks
A2: TANGO_1 Expedition | B2: AT_1 | C2: 44977 | D2: 44978 | E2: Henri Robert | I2: =IF(E2="","",_xlfn.LET(_xlpm.x,VLOOKUP(E2,'Drop-down_menus'!$D$2:$E$13,2,FALSE),IF(_xlpm.x=0,"",_xlpm.x))) | J2: =IF(F2="","",_xlfn.LET(_xlpm.x,VLOOKUP(F2,'Drop-down_menus'!$D$2:$E$13,2,FALSE),IF(_xlpm.x=0,"",_xlpm.x))) | K2: =IF(G2="","",_xlfn.LET(_xlpm.x,VLOOKUP(G2,'Drop-down_menus'!$D$2:$E$13,2,FALSE),IF(_xlpm.x=0,"",_xlpm.x))) | L2: =IF(H2="","",_xlfn.LET(_xlpm.x,VLOOKUP(H2,'Drop-down_menus'!$D$2:$E$13,2,FALSE),IF(_xlpm.x=0,"",_xlpm.x))) | M2: 0.42361111 | N2: 0.6875 | Q2: 66 | R2: 0.083 | S2: 65 | T2: 47.249 | U2: 66 | V2: 0.0083 | W2: 65 | X2: 47.249 | Y2: =-(Q2+R2/60) -> -66.001383 | Z2: =-(S2+T2/60) -> -65.787483 | AA2: =-(U2+V2/60) -> -66.000138 | AB2: =-(W2+X2/60) -> -65.787483 | AC2: Dodman Island | AD2: 21 | AE2: 21 | AJ2: Amphipod Trap | AK2: Amphipod trap deployment and retrieval
A3: TANGO_1 Expedition | B3: AT_2 | C3: 44981 | D3: 44982 | E3: Henri Robert | I3: =IF(E3="","",_xlfn.LET(_xlpm.x,VLOOKUP(E3,'Drop-down_menus'!$D$2:$E$13,2,FALSE),IF(_xlpm.x=0,"",_xlpm.x))) | J3: =IF(F3="","",_xlfn.LET(_xlpm.x,VLOOKUP(F3,'Drop-down_menus'!$D$2:$E$13,2,FALSE),IF(_xlpm.x=0,"",_xlpm.x))) | K3: =IF(G3="","",_xlfn.LET(_xlpm.x,VLOOKUP(G3,'Drop-down_menus'!$D$2:$E$13,2,FALSE),IF(_xlpm.x=0,"",_xlpm.x))) | L3: =IF(H3="","",_xlfn.LET(_xlpm.x,VLOOKUP(H3,'Drop-down_menus'!$D$2:$E$13,2,FALSE),IF(_xlpm.x=0,"",_xlpm.x))) | M3: 0.5 | N3: 0.3125 | Q3: 65 | R3: 59.9 | S3: 65 | T3: 47.386 | U3: 66 | V3: 0.521 | W3: 65 | X3: 46.759 | Y3: =-(Q3+R3/60) -> -65.998333 | Z3: =-(S3+T3/60) -> -65.789767 | AA3: =-(U3+V3/60) -> -66.008683 | AB3: =-(W3+X3/60) -> -65.779317 | AC3: Dodman Island | AE3: 50 | AJ3: Amphipod Trap | AK3: Amphipod trap deployment and retrieval
A4: TANGO_1 Expedition | B4: AT_3 | C4: 44983 | D4: 44984 | E4: Henri Robert | I4: =IF(E4="","",_xlfn.LET(_xlpm.x,VLOOKUP(E4,'Drop-down_menus'!$D$2:$E$13,2,FALSE),IF(_xlpm.x=0,"",_xlpm.x))) | J4: =IF(F4="","",_xlfn.LET(_xlpm.x,VLOOKUP(F4,'Drop-down_menus'!$D$2:$E$13,2,FALSE),IF(_xlpm.x=0,"",_xlpm.x))) | K4: =IF(G4="","",_xlfn.LET(_xlpm.x,VLOOKUP(G4,'Drop-down_menus'!$D$2:$E$13,2,FALSE),IF(_xlpm.x=0,"",_xlpm.x))) | L4: =IF(H4="","",_xlfn.LET(_xlpm.x,VLOOKUP(H4,'Drop-down_menus'!$D$2:$E$13,2,FALSE),IF(_xlpm.x=0,"",_xlpm.x))) | M4: 0.47916667 | N4: 0.70833333 | Q4: 66 | R4: 0.575 | S4: 65 | T4: 46.303 | U4: 66 | V4: 0.5751 | W4: 65 | X4: 46.303 | Y4: =-(Q4+R4/60) -> -66.009583 | Z4: =-(S4+T4/60) -> -65.771717 | AC4: Dodman Island | AD4: 60 | AJ4: Amphipod Trap | AK4: Amphipod trap deployment and retrieval
A5: TANGO_1 Expedition | B5: AT_4 | C5: 44987 | D5: 44989 | E5: Henri Robert | I5: =IF(E5="","",_xlfn.LET(_xlpm.x,VLOOKUP(E5,'Drop-down_menus'!$D$2:$E$13,2,FALSE),IF(_xlpm.x=0,"",_xlpm.x))) | J5: =IF(F5="","",_xlfn.LET(_xlpm.x,VLOOKUP(F5,'Drop-down_menus'!$D$2:$E$13,2,FALSE),IF(_xlpm.x=0,"",_xlpm.x))) | K5: =IF(G5="","",_xlfn.LET(_xlpm.x,VLOOKUP(G5,'Drop-down_menus'!$D$2:$E$13,2,FALSE),IF(_xlpm.x=0,"",_xlpm.x))) | L5: =IF(H5="","",_xlfn.LET(_xlpm.x,VLOOKUP(H5,'Drop-down_menus'!$D$2:$E$13,2,FALSE),IF(_xlpm.x=0,"",_xlpm.x))) | M5: 0.54166667 | N5: 0.35416667 | Q5: 67 | R5: 33.222 | S5: 67 | T5: 13.146 | U5: 67 | V5: 33.222 | W5: 67 | X5: 13.146 | Y5: =-(Q5+R5/60) -> -67.5537 | Z5: =-(S5+T5/60) -> -67.2191 | AC5: Blaiklock Island | AE5: 24 | AJ5: Amphipod Trap | AK5: Amphipod trap deployment and retrieval
A6: TANGO_1 Expedition | B6: AT_5 | C6: 44990 | D6: 44992 | E6: Henri Robert | I6: =IF(E6="","",_xlfn.LET(_xlpm.x,VLOOKUP(E6,'Drop-down_menus'!$D$2:$E$13,2,FALSE),IF(_xlpm.x=0,"",_xlpm.x))) | J6: =IF(F6="","",_xlfn.LET(_xlpm.x,VLOOKUP(F6,'Drop-down_menus'!$D$2:$E$13,2,FALSE),IF(_xlpm.x=0,"",_xlpm.x))) | K6: =IF(G6="","",_xlfn.LET(_xlpm.x,VLOOKUP(G6,'Drop-down_menus'!$D$2:$E$13,2,FALSE),IF(_xlpm.x=0,"",_xlpm.x))) | L6: =IF(H6="","",_xlfn.LET(_xlpm.x,VLOOKUP(H6,'Drop-down_menus'!$D$2:$E$13,2,FALSE),IF(_xlpm.x=0,"",_xlpm.x))) | M6: 0.77083333 | N6: 0.39583333 | Q6: 67 | R6: 30.9 | S6: 67 | T6: 5.977 | U6: 67 | V6: 30.9 | W6: 67 | X6: 5.977 | Y6: =-(Q6+R6/60) -> -67.515 | Z6: =-(S6+T6/60) -> -67.099617 | AC6: Blaiklock Island | AD6: 23 | AE6: 23 | AJ6: Amphipod Trap | AK6: Amphipod trap deployment and retrieval
A7: TANGO_1 Expedition | B7: BATHY_XX_1 | C7: 44986 | E7: Ben Wallis | I7: =IF(E7="","",_xlfn.LET(_xlpm.x,VLOOKUP(E7,'Drop-down_menus'!$D$2:$E$13,2,FALSE),IF(_xlpm.x=0,"",_xlpm.x))) | J7: =IF(F7="","",_xlfn.LET(_xlpm.x,VLOOKUP(F7,'Drop-down_menus'!$D$2:$E$13,2,FALSE),IF(_xlpm.x=0,"",_xlpm.x))) | K7: =IF(G7="","",_xlfn.LET(_xlpm.x,VLOOKUP(G7,'Drop-down_menus'!$D$2:$E$13,2,FALSE),IF(_xlpm.x=0,"",_xlpm.x))) | L7: =IF(H7="","",_xlfn.LET(_xlpm.x,VLOOKUP(H7,'Drop-down_menus'!$D$2:$E$13,2,FALSE),IF(_xlpm.x=0,"",_xlpm.x))) | Y7: =-(Q7+R7/60) -> 0 | Z7: =-(S7+T7/60) -> 0 | AA7: =-(U7+V7/60) -> 0 | AB7: =-(W7+X7/60) -> 0 | AC7: Blaiklock Island | AJ7: Mavic 2 PRO drone aerial mapping | AK7: DroneDeploy Photogrammetry
A8: TANGO_1 Expedition | B8: BATHY_XX_2 | C8: 44987 | E8: Ben Wallis | I8: =IF(E8="","",_xlfn.LET(_xlpm.x,VLOOKUP(E8,'Drop-down_menus'!$D$2:$E$13,2,FALSE),IF(_xlpm.x=0,"",_xlpm.x))) | J8: =IF(F8="","",_xlfn.LET(_xlpm.x,VLOOKUP(F8,'Drop-down_menus'!$D$2:$E$13,2,FALSE),IF(_xlpm.x=0,"",_xlpm.x))) | K8: =IF(G8="","",_xlfn.LET(_xlpm.x,VLOOKUP(G8,'Drop-down_menus'!$D$2:$E$13,2,FALSE),IF(_xlpm.x=0,"",_xlpm.x))) | L8: =IF(H8="","",_xlfn.LET(_xlpm.x,VLOOKUP(H8,'Drop-down_menus'!$D$2:$E$13,2,FALSE),IF(_xlpm.x=0,"",_xlpm.x))) | Y8: =-(Q8+R8/60) -> 0 | Z8: =-(S8+T8/60) -> 0 | AA8: =-(U8+V8/60) -> 0 | AB8: =-(W8+X8/60) -> 0 | AC8: Blaiklock Island | AJ8: Fine-scale bathymetry
A9: TANGO_1 Expedition | B9: BATHY_XX_3 | C9: 44988 | E9: Ben Wallis | I9: =IF(E9="","",_xlfn.LET(_xlpm.x,VLOOKUP(E9,'Drop-down_menus'!$D$2:$E$13,2,FALSE),IF(_xlpm.x=0,"",_xlpm.x))) | J9: =IF(F9="","",_xlfn.LET(_xlpm.x,VLOOKUP(F9,'Drop-down_menus'!$D$2:$E$13,2,FALSE),IF(_xlpm.x=0,"",_xlpm.x))) | K9: =IF(G9="","",_xlfn.LET(_xlpm.x,VLOOKUP(G9,'Drop-down_menus'!$D$2:$E$13,2,FALSE),IF(_xlpm.x=0,"",_xlpm.x))) | L9: =IF(H9="","",_xlfn.LET(_xlpm.x,VLOOKUP(H9,'Drop-down_menus'!$D$2:$E$13,2,FALSE),IF(_xlpm.x=0,"",_xlpm.x))) | Y9: =-(Q9+R9/60) -> 0 | Z9: =-(S9+T9/60) -> 0 | AA9: =-(U9+V9/60) -> 0 | AB9: =-(W9+X9/60) -> 0 | AC9: Blaiklock Island | AJ9: Mavic 2 PRO drone aerial mapping | AK9: DroneDeploy Photogrammetry
A10: TANGO_1 Expedition | B10: BATHY_XX_4 | C10: 44988 | E10: Ben Wallis | I10: =IF(E10="","",_xlfn.LET(_xlpm.x,VLOOKUP(E10,'Drop-down_menus'!$D$2:$E$13,2,FALSE),IF(_xlpm.x=0,"",_xlpm.x))) | J10: =IF(F10="","",_xlfn.LET(_xlpm.x,VLOOKUP(F10,'Drop-down_menus'!$D$2:$E$13,2,FALSE),IF(_xlpm.x=0,"",_xlpm.x))) | K10: =IF(G10="","",_xlfn.LET(_xlpm.x,VLOOKUP(G10,'Drop-down_menus'!$D$2:$E$13,2,FALSE),IF(_xlpm.x=0,"",_xlpm.x))) | L10: =IF(H10="","",_xlfn.LET(_xlpm.x,VLOOKUP(H10,'Drop-down_menus'!$D$2:$E$13,2,FALSE),IF(_xlpm.x=0,"",_xlpm.x))) | Y10: =-(Q10+R10/60) -> 0 | Z10: =-(S10+T10/60) -> 0 | AA10: =-(U10+V10/60) -> 0 | AB10: =-(W10+X10/60) -> 0 | AC10: Blaiklock Island | AJ10: Fine-scale bathymetry
A11: TANGO_1 Expedition | B11: CTD_1 | C11: 44976 | E11: Axelle Brusselman | I11: =IF(E11="","",_xlfn.LET(_xlpm.x,VLOOKUP(E11,'Drop-down_menus'!$D$2:$E$13,2,FALSE),IF(_xlpm.x=0,"",_xlpm.x))) -> https://orcid.org/0009-0002-6669-2911 | J11: =IF(F11="","",_xlfn.LET(_xlpm.x,VLOOKUP(F11,'Drop-down_menus'!$D$2:$E$13,2,FALSE),IF(_xlpm.x=0,"",_xlpm.x))) | K11: =IF(G11="","",_xlfn.LET(_xlpm.x,VLOOKUP(G11,'Drop-down_menus'!$D$2:$E$13,2,FALSE),IF(_xlpm.x=0,"",_xlpm.x))) | L11: =IF(H11="","",_xlfn.LET(_xlpm.x,VLOOKUP(H11,'Drop-down_menus'!$D$2:$E$13,2,FALSE),IF(_xlpm.x=0,"",_xlpm.x))) | M11: 0.75 | N11: 0.77083333 | Q11: 66 | R11: 0.016 | S11: 65 | T11: 46.643 | Y11: =-(Q11+R11/60) -> -66.000267 | Z11: =-(S11+T11/60) -> -65.777383 | AA11: =-(U11+V11/60) -> 0 | AB11: =-(W11+X11/60) -> 0 | AC11: Dodman Island | AD11: 0 | AE11: 0 | AJ11: STAR_ODDI DST CTD
A12: TANGO_1 Expedition | B12: CTD_11 | C12: 44990 | E12: Axelle Brusselman | F12: Bruno Delille | G12: Bruno Danis | I12: =IF(E12="","",_xlfn.LET(_xlpm.x,VLOOKUP(E12,'Drop-down_menus'!$D$2:$E$13,2,FALSE),IF(_xlpm.x=0,"",_xlpm.x))) -> https://orcid.org/0009-0002-6669-2911 | J12: =IF(F12="","",_xlfn.LET(_xlpm.x,VLOOKUP(F12,'Drop-down_menus'!$D$2:$E$13,2,FALSE),IF(_xlpm.x=0,"",_xlpm.x))) -> https://orcid.org/0000-0003-0502-8101 | K12: =IF(G12="","",_xlfn.LET(_xlpm.x,VLOOKUP(G12,'Drop-down_menus'!$D$2:$E$13,2,FALSE),IF(_xlpm.x=0,"",_xlpm.x))) -> https://orcid.org/0000-0002-9037-7623 | L12: =IF(H12="","",_xlfn.LET(_xlpm.x,VLOOKUP(H12,'Drop-down_menus'!$D$2:$E$13,2,FALSE),IF(_xlpm.x=0,"",_xlpm.x))) | M12: 0.60625 | N12: 0.625 | Q12: 67 | R12: 30.3081 | S12: 67 | T12: 3.104 | Y12: =-(Q12+R12/60) -> -67.505135 | Z12: =-(S12+T12/60) -> -67.051733 | AA12: =-(U12+V12/60) -> 0 | AB12: =-(W12+X12/60) -> 0 | AC12: Blaiklock Island | AE12: 19.2 | AJ12: CTD casts
A13: TANGO_1 Expedition | B13: CTD_13 | C13: 44992 | E13: Bruno Delille | F13: Axelle Brusselman | I13: =IF(E13="","",_xlfn.LET(_xlpm.x,VLOOKUP(E13,'Drop-down_menus'!$D$2:$E$13,2,FALSE),IF(_xlpm.x=0,"",_xlpm.x))) -> https://orcid.org/0000-0003-0502-8101 | J13: =IF(F13="","",_xlfn.LET(_xlpm.x,VLOOKUP(F13,'Drop-down_menus'!$D$2:$E$13,2,FALSE),IF(_xlpm.x=0,"",_xlpm.x))) -> https://orcid.org/0009-0002-6669-2911 | K13: =IF(G13="","",_xlfn.LET(_xlpm.x,VLOOKUP(G13,'Drop-down_menus'!$D$2:$E$13,2,FALSE),IF(_xlpm.x=0,"",_xlpm.x))) | L13: =IF(H13="","",_xlfn.LET(_xlpm.x,VLOOKUP(H13,'Drop-down_menus'!$D$2:$E$13,2,FALSE),IF(_xlpm.x=0,"",_xlpm.x))) | M13: 0.42708333 | N13: 0.44791667 | Q13: 67 | R13: 30.905 | S13: 67 | T13: 5.999 | Y13: =-(Q13+R13/60) -> -67.515083 | Z13: =-(S13+T13/60) -> -67.099983 | AA13: =-(U13+V13/60) -> 0 | AB13: =-(W13+X13/60) -> 0 | AC13: Blaiklock Island | AJ13: CTD casts
A14: TANGO_1 Expedition | B14: CTD_14 | C14: 44992 | E14: Bruno Delille | F14: Axelle Brusselman | I14: =IF(E14="","",_xlfn.LET(_xlpm.x,VLOOKUP(E14,'Drop-down_menus'!$D$2:$E$13,2,FALSE),IF(_xlpm.x=0,"",_xlpm.x))) -> https://orcid.org/0000-0003-0502-8101 | J14: =IF(F14="","",_xlfn.LET(_xlpm.x,VLOOKUP(F14,'Drop-down_menus'!$D$2:$E$13,2,FALSE),IF(_xlpm.x=0,"",_xlpm.x))) -> https://orcid.org/0009-0002-6669-2911 | K14: =IF(G14="","",_xlfn.LET(_xlpm.x,VLOOKUP(G14,'Drop-down_menus'!$D$2:$E$13,2,FALSE),IF(_xlpm.x=0,"",_xlpm.x))) | L14: =IF(H14="","",_xlfn.LET(_xlpm.x,VLOOKUP(H14,'Drop-down_menus'!$D$2:$E$13,2,FALSE),IF(_xlpm.x=0,"",_xlpm.x))) | M14: 0.60138889 | N14: 0.62847222 | Q14: 67 | R14: 30.195 | S14: 67 | T14: 7.834 | Y14: =-(Q14+R14/60) -> -67.50325 | Z14: =-(S14+T14/60) -> -67.130567 | AA14: =-(U14+V14/60) -> 0 | AB14: =-(W14+X14/60) -> 0 | AC14: Blaiklock Island | AJ14: CTD casts
A15: TANGO_1 Expedition | B15: CTD_2 | C15: 44977 | E15: Bruno Delille | F15: Axelle Brusselman | I15: =IF(E15="","",_xlfn.LET(_xlpm.x,VLOOKUP(E15,'Drop-down_menus'!$D$2:$E$13,2,FALSE),IF(_xlpm.x=0,"",_xlpm.x))) -> https://orcid.org/0000-0003-0502-8101 | J15: =IF(F15="","",_xlfn.LET(_xlpm.x,VLOOKUP(F15,'Drop-down_menus'!$D$2:$E$13,2,FALSE),IF(_xlpm.x=0,"",_xlpm.x))) -> https://orcid.org/0009-0002-6669-2911 | K15: =IF(G15="","",_xlfn.LET(_xlpm.x,VLOOKUP(G15,'Drop-down_menus'!$D$2:$E$13,2,FALSE),IF(_xlpm.x=0,"",_xlpm.x))) | L15: =IF(H15="","",_xlfn.LET(_xlpm.x,VLOOKUP(H15,'Drop-down_menus'!$D$2:$E$13,2,FALSE),IF(_xlpm.x=0,"",_xlpm.x))) | M15: 0.35069444 | N15: 0.375 | Q15: 66 | R15: 0.016 | S15: 65 | T15: 46.643 | Y15: =-(Q15+R15/60) -> -66.000267 | Z15: =-(S15+T15/60) -> -65.777383 | AA15: =-(U15+V15/60) -> 0 | AB15: =-(W15+X15/60) -> 0 | AC15: Dodman Island | AD15: 0 | AJ15: STAR_ODDI DST CTD | AK15: Test
A16: TANGO_1 Expedition | B16: CTD_3 | C16: 44977 | E16: Bruno Delille | F16: Axelle Brusselman | I16: =IF(E16="","",_xlfn.LET(_xlpm.x,VLOOKUP(E16,'Drop-down_menus'!$D$2:$E$13,2,FALSE),IF(_xlpm.x=0,"",_xlpm.x))) -> https://orcid.org/0000-0003-0502-8101 | J16: =IF(F16="","",_xlfn.LET(_xlpm.x,VLOOKUP(F16,'Drop-down_menus'!$D$2:$E$13,2,FALSE),IF(_xlpm.x=0,"",_xlpm.x))) -> https://orcid.org/0009-0002-6669-2911 | K16: =IF(G16="","",_xlfn.LET(_xlpm.x,VLOOKUP(G16,'Drop-down_menus'!$D$2:$E$13,2,FALSE),IF(_xlpm.x=0,"",_xlpm.x))) | L16: =IF(H16="","",_xlfn.LET(_xlpm.x,VLOOKUP(H16,'Drop-down_menus'!$D$2:$E$13,2,FALSE),IF(_xlpm.x=0,"",_xlpm.x))) | M16: 0.43055556 | N16: 0.4375 | Q16: 66 | R16: 0.016 | S16: 65 | T16: 46.643 | Y16: =-(Q16+R16/60) -> -66.000267 | Z16: =-(S16+T16/60) -> -65.777383 | AA16: =-(U16+V16/60) -> 0 | AB16: =-(W16+X16/60) -> 0 | AC16: Dodman Island | AD16: 0 | AJ16: STAR_ODDI DST CTD | AK16: Test
A17: TANGO_1 Expedition | B17: CTD_4 | C17: 44977 | E17: Bruno Delille | F17: Axelle Brusselman | I17: =IF(E17="","",_xlfn.LET(_xlpm.x,VLOOKUP(E17,'Drop-down_menus'!$D$2:$E$13,2,FALSE),IF(_xlpm.x=0,"",_xlpm.x))) -> https://orcid.org/0000-0003-0502-8101 | J17: =IF(F17="","",_xlfn.LET(_xlpm.x,VLOOKUP(F17,'Drop-down_menus'!$D$2:$E$13,2,FALSE),IF(_xlpm.x=0,"",_xlpm.x))) -> https://orcid.org/0009-0002-6669-2911 | K17: =IF(G17="","",_xlfn.LET(_xlpm.x,VLOOKUP(G17,'Drop-down_menus'!$D$2:$E$13,2,FALSE),IF(_xlpm.x=0,"",_xlpm.x))) | L17: =IF(H17="","",_xlfn.LET(_xlpm.x,VLOOKUP(H17,'Drop-down_menus'!$D$2:$E$13,2,FALSE),IF(_xlpm.x=0,"",_xlpm.x))) | M17: 0.47152778 | N17: 0.5 | Q17: 66 | R17: 0.016 | S17: 65 | T17: 46.643 | Y17: =-(Q17+R17/60) -> -66.000267 | Z17: =-(S17+T17/60) -> -65.777383 | AA17: =-(U17+V17/60) -> 0 | AB17: =-(W17+X17/60) -> 0 | AC17: Dodman Island | AD17: 0 | AJ17: STAR_ODDI DST CTD
A18: TANGO_1 Expedition | B18: CTD_5 | C18: 44978 | E18: Bruno Delille | F18: Axelle Brusselman | I18: =IF(E18="","",_xlfn.LET(_xlpm.x,VLOOKUP(E18,'Drop-down_menus'!$D$2:$E$13,2,FALSE),IF(_xlpm.x=0,"",_xlpm.x))) -> https://orcid.org/0000-0003-0502-8101 | J18: =IF(F18="","",_xlfn.LET(_xlpm.x,VLOOKUP(F18,'Drop-down_menus'!$D$2:$E$13,2,FALSE),IF(_xlpm.x=0,"",_xlpm.x))) -> https://orcid.org/0009-0002-6669-2911 | K18: =IF(G18="","",_xlfn.LET(_xlpm.x,VLOOKUP(G18,'Drop-down_menus'!$D$2:$E$13,2,FALSE),IF(_xlpm.x=0,"",_xlpm.x))) | L18: =IF(H18="","",_xlfn.LET(_xlpm.x,VLOOKUP(H18,'Drop-down_menus'!$D$2:$E$13,2,FALSE),IF(_xlpm.x=0,"",_xlpm.x))) | M18: 0.36944444 | N18: 0.37083333 | Q18: 66 | R18: 0.016 | S18: 65 | T18: 46.643 | Y18: =-(Q18+R18/60) -> -66.000267 | Z18: =-(S18+T18/60) -> -65.777383 | AA18: =-(U18+V18/60) -> 0 | AB18: =-(W18+X18/60) -> 0 | AC18: Dodman Island | AD18: 0 | AE18: 16.3 | AJ18: CTD casts
A19: TANGO_1 Expedition | B19: CTD_6 | C19: 44980 | E19: Bruno Delille | F19: Axelle Brusselman | I19: =IF(E19="","",_xlfn.LET(_xlpm.x,VLOOKUP(E19,'Drop-down_menus'!$D$2:$E$13,2,FALSE),IF(_xlpm.x=0,"",_xlpm.x))) -> https://orcid.org/0000-0003-0502-8101 | J19: =IF(F19="","",_xlfn.LET(_xlpm.x,VLOOKUP(F19,'Drop-down_menus'!$D$2:$E$13,2,FALSE),IF(_xlpm.x=0,"",_xlpm.x))) -> https://orcid.org/0009-0002-6669-2911 | K19: =IF(G19="","",_xlfn.LET(_xlpm.x,VLOOKUP(G19,'Drop-down_menus'!$D$2:$E$13,2,FALSE),IF(_xlpm.x=0,"",_xlpm.x))) | L19: =IF(H19="","",_xlfn.LET(_xlpm.x,VLOOKUP(H19,'Drop-down_menus'!$D$2:$E$13,2,FALSE),IF(_xlpm.x=0,"",_xlpm.x))) | M19: 0.49444444 | N19: 0.49652778 | Q19: 66 | R19: 0.027 | S19: 65 | T19: 46.75 | Y19: =-(Q19+R19/60) -> -66.00045 | Z19: =-(S19+T19/60) -> -65.779167 | AA19: =-(U19+V19/60) -> 0 | AB19: =-(W19+X19/60) -> 0 | AC19: Dodman Island | AJ19: CTD casts
A20: TANGO_1 Expedition | B20: CTD_7 | C20: 44982 | E20: Bruno Delille | F20: Axelle Brusselman | I20: =IF(E20="","",_xlfn.LET(_xlpm.x,VLOOKUP(E20,'Drop-down_menus'!$D$2:$E$13,2,FALSE),IF(_xlpm.x=0,"",_xlpm.x))) -> https://orcid.org/0000-0003-0502-8101 | J20: =IF(F20="","",_xlfn.LET(_xlpm.x,VLOOKUP(F20,'Drop-down_menus'!$D$2:$E$13,2,FALSE),IF(_xlpm.x=0,"",_xlpm.x))) -> https://orcid.org/0009-0002-6669-2911 | K20: =IF(G20="","",_xlfn.LET(_xlpm.x,VLOOKUP(G20,'Drop-down_menus'!$D$2:$E$13,2,FALSE),IF(_xlpm.x=0,"",_xlpm.x))) | L20: =IF(H20="","",_xlfn.LET(_xlpm.x,VLOOKUP(H20,'Drop-down_menus'!$D$2:$E$13,2,FALSE),IF(_xlpm.x=0,"",_xlpm.x))) | M20: 0.6875 | N20: 0.70138889 | Q20: 66 | R20: 1.225 | S20: 65 | T20: 50.694 | Y20: =-(Q20+R20/60) -> -66.020417 | Z20: =-(S20+T20/60) -> -65.8449 | AA20: =-(U20+V20/60) -> 0 | AB20: =-(W20+X20/60) -> 0 | AC20: Grandidier Channel | AD20: 0 | AE20: 100 | AJ20: CTD casts
A21: TANGO_1 Expedition | B21: CTD_8 | C21: 44987 | E21: Bruno Delille | F21: Axelle Brusselman | I21: =IF(E21="","",_xlfn.LET(_xlpm.x,VLOOKUP(E21,'Drop-down_menus'!$D$2:$E$13,2,FALSE),IF(_xlpm.x=0,"",_xlpm.x))) -> https://orcid.org/0000-0003-0502-8101 | J21: =IF(F21="","",_xlfn.LET(_xlpm.x,VLOOKUP(F21,'Drop-down_menus'!$D$2:$E$13,2,FALSE),IF(_xlpm.x=0,"",_xlpm.x))) -> https://orcid.org/0009-0002-6669-2911 | K21: =IF(G21="","",_xlfn.LET(_xlpm.x,VLOOKUP(G21,'Drop-down_menus'!$D$2:$E$13,2,FALSE),IF(_xlpm.x=0,"",_xlpm.x))) | L21: =IF(H21="","",_xlfn.LET(_xlpm.x,VLOOKUP(H21,'Drop-down_menus'!$D$2:$E$13,2,FALSE),IF(_xlpm.x=0,"",_xlpm.x))) | M21: 0.4625 | N21: 0.49305556 | Q21: 67 | R21: 33.112 | S21: 67 | T21: 12.89 | Y21: =-(Q21+R21/60) -> -67.551867 | Z21: =-(S21+T21/60) -> -67.214833 | AA21: =-(U21+V21/60) -> 0 | AB21: =-(W21+X21/60) -> 0 | AC21: Blaiklock Island | AJ21: CTD casts
A22: TANGO_1 Expedition | B22: CTD_9 | C22: 44989 | E22: Bruno Delille | F22: Axelle Brusselman | I22: =IF(E22="","",_xlfn.LET(_xlpm.x,VLOOKUP(E22,'Drop-down_menus'!$D$2:$E$13,2,FALSE),IF(_xlpm.x=0,"",_xlpm.x))) -> https://orcid.org/0000-0003-0502-8101 | J22: =IF(F22="","",_xlfn.LET(_xlpm.x,VLOOKUP(F22,'Drop-down_menus'!$D$2:$E$13,2,FALSE),IF(_xlpm.x=0,"",_xlpm.x))) -> https://orcid.org/0009-0002-6669-2911 | K22: =IF(G22="","",_xlfn.LET(_xlpm.x,VLOOKUP(G22,'Drop-down_menus'!$D$2:$E$13,2,FALSE),IF(_xlpm.x=0,"",_xlpm.x))) | L22: =IF(H22="","",_xlfn.LET(_xlpm.x,VLOOKUP(H22,'Drop-down_menus'!$D$2:$E$13,2,FALSE),IF(_xlpm.x=0,"",_xlpm.x))) | M22: 0.46527778 | N22: 0.47222222 | Q22: 67 | R22: 32.994 | S22: 67 | T22: 14.852 | Y22: =-(Q22+R22/60) -> -67.5499 | Z22: =-(S22+T22/60) -> -67.247533 | AA22: =-(U22+V22/60) -> 0 | AB22: =-(W22+X22/60) -> 0 | AC22: Blaiklock Island | AD22: 0 | AE22: 16 | AJ22: CTD casts
A23: TANGO_1 Expedition | B23: CYANO_1 | C23: 44979 | E23: Bruno Delille | F23: Axelle Brusselman | I23: =IF(E23="","",_xlfn.LET(_xlpm.x,VLOOKUP(E23,'Drop-down_menus'!$D$2:$E$13,2,FALSE),IF(_xlpm.x=0,"",_xlpm.x))) -> https://orcid.org/0000-0003-0502-8101 | J23: =IF(F23="","",_xlfn.LET(_xlpm.x,VLOOKUP(F23,'Drop-down_menus'!$D$2:$E$13,2,FALSE),IF(_xlpm.x=0,"",_xlpm.x))) -> https://orcid.org/0009-0002-6669-2911 | K23: =IF(G23="","",_xlfn.LET(_xlpm.x,VLOOKUP(G23,'Drop-down_menus'!$D$2:$E$13,2,FALSE),IF(_xlpm.x=0,"",_xlpm.x))) | L23: =IF(H23="","",_xlfn.LET(_xlpm.x,VLOOKUP(H23,'Drop-down_menus'!$D$2:$E$13,2,FALSE),IF(_xlpm.x=0,"",_xlpm.x))) | M23: 0.78125 | N23: 0.79166667 | Y23: -65.4686 | Z23: -65.996 | AC23: Dodman Island | AE23: 0 | AJ23: Cyanobacteria sampling
A24: TANGO_1 Expedition | B24: CYANO_2 | C24: 44980 | E24: Bruno Delille | F24: Axelle Brusselman | I24: =IF(E24="","",_xlfn.LET(_xlpm.x,VLOOKUP(E24,'Drop-down_menus'!$D$2:$E$13,2,FALSE),IF(_xlpm.x=0,"",_xlpm.x))) -> https://orcid.org/0000-0003-0502-8101 | J24: =IF(F24="","",_xlfn.LET(_xlpm.x,VLOOKUP(F24,'Drop-down_menus'!$D$2:$E$13,2,FALSE),IF(_xlpm.x=0,"",_xlpm.x))) -> https://orcid.org/0009-0002-6669-2911 | K24: =IF(G24="","",_xlfn.LET(_xlpm.x,VLOOKUP(G24,'Drop-down_menus'!$D$2:$E$13,2,FALSE),IF(_xlpm.x=0,"",_xlpm.x))) | L24: =IF(H24="","",_xlfn.LET(_xlpm.x,VLOOKUP(H24,'Drop-down_menus'!$D$2:$E$13,2,FALSE),IF(_xlpm.x=0,"",_xlpm.x))) | M24: 0.75486111 | N24: 0.76875 | Q24: 65 | R24: 59.94 | S24: 65 | T24: 46.87 | Y24: =-(Q24+R24/60) -> -65.999 | Z24: =-(S24+T24/60) -> -65.781167 | AA24: =-(U24+V24/60) -> 0 | AB24: =-(W24+X24/60) -> 0 | AC24: Dodman Island | AJ24: Cyanobacteria sampling
A25: TANGO_1 Expedition | B25: CYANO_3 | C25: 44984 | E25: Axelle Brusselman | F25: Maria Amenabar | G25: Annette Bombosch | I25: =IF(E25="","",_xlfn.LET(_xlpm.x,VLOOKUP(E25,'Drop-down_menus'!$D$2:$E$13,2,FALSE),IF(_xlpm.x=0,"",_xlpm.x))) -> https://orcid.org/0009-0002-6669-2911 | J25: =IF(F25="","",_xlfn.LET(_xlpm.x,VLOOKUP(F25,'Drop-down_menus'!$D$2:$E$13,2,FALSE),IF(_xlpm.x=0,"",_xlpm.x))) | K25: =IF(G25="","",_xlfn.LET(_xlpm.x,VLOOKUP(G25,'Drop-down_menus'!$D$2:$E$13,2,FALSE),IF(_xlpm.x=0,"",_xlpm.x))) | L25: =IF(H25="","",_xlfn.LET(_xlpm.x,VLOOKUP(H25,'Drop-down_menus'!$D$2:$E$13,2,FALSE),IF(_xlpm.x=0,"",_xlpm.x))) | M25: 0.6625 | N25: 0.69444444 | Q25: 66 | R25: 0.05715 | S25: 65 | T25: 46.4785 | Y25: =-(Q25+R25/60) -> -66.000952 | Z25: =-(S25+T25/60) -> -65.774642 | AA25: =-(U25+V25/60) -> 0 | AB25: =-(W25+X25/60) -> 0 | AC25: Dodman Island | AJ25: Cyanobacteria sampling
A26: TANGO_1 Expedition | B26: CYANO_4 | C26: 44984 | E26: Axelle Brusselman | F26: Maria Amenabar | G26: Annette Bombosch | I26: =IF(E26="","",_xlfn.LET(_xlpm.x,VLOOKUP(E26,'Drop-down_menus'!$D$2:$E$13,2,FALSE),IF(_xlpm.x=0,"",_xlpm.x))) -> https://orcid.org/0009-0002-6669-2911 | J26: =IF(F26="","",_xlfn.LET(_xlpm.x,VLOOKUP(F26,'Drop-down_menus'!$D$2:$E$13,2,FALSE),IF(_xlpm.x=0,"",_xlpm.x))) | K26: =IF(G26="","",_xlfn.LET(_xlpm.x,VLOOKUP(G26,'Drop-down_menus'!$D$2:$E$13,2,FALSE),IF(_xlpm.x=0,"",_xlpm.x))) | L26: =IF(H26="","",_xlfn.LET(_xlpm.x,VLOOKUP(H26,'Drop-down_menus'!$D$2:$E$13,2,FALSE),IF(_xlpm.x=0,"",_xlpm.x))) | M26: 0.70138889 | N26: 0.72916667 | Q26: 66 | R26: 0.0965 | S26: 65 | T26: 45.842 | Y26: =-(Q26+R26/60) -> -66.001608 | Z26: =-(S26+T26/60) -> -65.764033 | AA26: =-(U26+V26/60) -> 0 | AB26: =-(W26+X26/60) -> 0 | AC26: Dodman Island | AJ26: Cyanobacteria sampling
A27: TANGO_1 Expedition | B27: CYANO_5 | C27: 44987 | E27: Axelle Brusselman | I27: =IF(E27="","",_xlfn.LET(_xlpm.x,VLOOKUP(E27,'Drop-down_menus'!$D$2:$E$13,2,FALSE),IF(_xlpm.x=0,"",_xlpm.x))) -> https://orcid.org/0009-0002-6669-2911 | J27: =IF(F27="","",_xlfn.LET(_xlpm.x,VLOOKUP(F27,'Drop-down_menus'!$D$2:$E$13,2,FALSE),IF(_xlpm.x=0,"",_xlpm.x))) | K27: =IF(G27="","",_xlfn.LET(_xlpm.x,VLOOKUP(G27,'Drop-down_menus'!$D$2:$E$13,2,FALSE),IF(_xlpm.x=0,"",_xlpm.x))) | L27: =IF(H27="","",_xlfn.LET(_xlpm.x,VLOOKUP(H27,'Drop-down_menus'!$D$2:$E$13,2,FALSE),IF(_xlpm.x=0,"",_xlpm.x))) | M27: 0.68055556 | N27: 0.72916667 | Q27: 67 | R27: 33.1841 | S27: 67 | T27: 12.6956 | Y27: =-(Q27+R27/60) -> -67.553068 | Z27: =-(S27+T27/60) -> -67.211593 | AA27: =-(U27+V27/60) -> 0 | AB27: =-(W27+X27/60) -> 0 | AC27: Blaiklock Island | AJ27: Cyanobacteria sampling
A28: TANGO_1 Expedition | B28: DR_1 | C28: 44976 | E28: Bruno Danis | I28: =IF(E28="","",_xlfn.LET(_xlpm.x,VLOOKUP(E28,'Drop-down_menus'!$D$2:$E$13,2,FALSE),IF(_xlpm.x=0,"",_xlpm.x))) -> https://orcid.org/0000-0002-9037-7623 | J28: =IF(F28="","",_xlfn.LET(_xlpm.x,VLOOKUP(F28,'Drop-down_menus'!$D$2:$E$13,2,FALSE),IF(_xlpm.x=0,"",_xlpm.x))) | K28: =IF(G28="","",_xlfn.LET(_xlpm.x,VLOOKUP(G28,'Drop-down_menus'!$D$2:$E$13,2,FALSE),IF(_xlpm.x=0,"",_xlpm.x))) | L28: =IF(H28="","",_xlfn.LET(_xlpm.x,VLOOKUP(H28,'Drop-down_menus'!$D$2:$E$13,2,FALSE),IF(_xlpm.x=0,"",_xlpm.x))) | M28: 0.38680556 | N28: 0.39375 | Q28: 66 | R28: 0.016 | S28: 65 | T28: 46.643 | Y28: =-(Q28+R28/60) -> -66.000267 | Z28: =-(S28+T28/60) -> -65.777383 | AA28: =-(U28+V28/60) -> 0 | AB28: =-(W28+X28/60) -> 0 | AC28: Dodman Island | AF28: 500 | AJ28: Mavic 2 PRO drone aerial mapping | AK28: Scouting, 500m alt
A29: TANGO_1 Expedition | B29: DR_2 | C29: 44988 | E29: Bruno Danis | I29: =IF(E29="","",_xlfn.LET(_xlpm.x,VLOOKUP(E29,'Drop-down_menus'!$D$2:$E$13,2,FALSE),IF(_xlpm.x=0,"",_xlpm.x))) -> https://orcid.org/0000-0002-9037-7623 | J29: =IF(F29="","",_xlfn.LET(_xlpm.x,VLOOKUP(F29,'Drop-down_menus'!$D$2:$E$13,2,FALSE),IF(_xlpm.x=0,"",_xlpm.x))) | K29: =IF(G29="","",_xlfn.LET(_xlpm.x,VLOOKUP(G29,'Drop-down_menus'!$D$2:$E$13,2,FALSE),IF(_xlpm.x=0,"",_xlpm.x))) | L29: =IF(H29="","",_xlfn.LET(_xlpm.x,VLOOKUP(H29,'Drop-down_menus'!$D$2:$E$13,2,FALSE),IF(_xlpm.x=0,"",_xlpm.x))) | M29: 0.39444444 | N29: 0.44791667 | Q29: 67 | R29: 33.112 | S29: 67 | T29: 12.89 | Y29: =-(Q29+R29/60) -> -67.551867 | Z29: =-(S29+T29/60) -> -67.214833 | AA29: =-(U29+V29/60) -> 0 | AB29: =-(W29+X29/60) -> 0 | AC29: Blaiklock Island | AF29: 500 | AJ29: Mavic 2 PRO drone aerial mapping
A30: TANGO_1 Expedition | B30: DR_5 | C30: 44992 | E30: Bruno Danis | I30: =IF(E30="","",_xlfn.LET(_xlpm.x,VLOOKUP(E30,'Drop-down_menus'!$D$2:$E$13,2,FALSE),IF(_xlpm.x=0,"",_xlpm.x))) -> https://orcid.org/0000-0002-9037-7623 | J30: =IF(F30="","",_xlfn.LET(_xlpm.x,VLOOKUP(F30,'Drop-down_menus'!$D$2:$E$13,2,FALSE),IF(_xlpm.x=0,"",_xlpm.x))) | K30: =IF(G30="","",_xlfn.LET(_xlpm.x,VLOOKUP(G30,'Drop-down_menus'!$D$2:$E$13,2,FALSE),IF(_xlpm.x=0,"",_xlpm.x))) | L30: =IF(H30="","",_xlfn.LET(_xlpm.x,VLOOKUP(H30,'Drop-down_menus'!$D$2:$E$13,2,FALSE),IF(_xlpm.x=0,"",_xlpm.x))) | M30: 0.38194444 | N30: 0.38541667 | Q30: 67 | R30: 30.905 | S30: 67 | T30: 5.999 | Y30: =-(Q30+R30/60) -> -67.515083 | Z30: =-(S30+T30/60) -> -67.099983 | AA30: =-(U30+V30/60) -> 0 | AB30: =-(W30+X30/60) -> 0 | AC30: Blaiklock Island | AJ30: Mavic 2 PRO drone aerial mapping
A31: TANGO_1 Expedition | B31: DRM_1 | C31: 44977 | E31: Bruno Danis | I31: =IF(E31="","",_xlfn.LET(_xlpm.x,VLOOKUP(E31,'Drop-down_menus'!$D$2:$E$13,2,FALSE),IF(_xlpm.x=0,"",_xlpm.x))) -> https://orcid.org/0000-0002-9037-7623 | J31: =IF(F31="","",_xlfn.LET(_xlpm.x,VLOOKUP(F31,'Drop-down_menus'!$D$2:$E$13,2,FALSE),IF(_xlpm.x=0,"",_xlpm.x))) | K31: =IF(G31="","",_xlfn.LET(_xlpm.x,VLOOKUP(G31,'Drop-down_menus'!$D$2:$E$13,2,FALSE),IF(_xlpm.x=0,"",_xlpm.x))) | L31: =IF(H31="","",_xlfn.LET(_xlpm.x,VLOOKUP(H31,'Drop-down_menus'!$D$2:$E$13,2,FALSE),IF(_xlpm.x=0,"",_xlpm.x))) | M31: 0.68055556 | N31: 0.69444444 | Q31: 66 | R31: 0.016 | S31: 65 | T31: 46.643 | Y31: =-(Q31+R31/60) -> -66.000267 | Z31: =-(S31+T31/60) -> -65.777383 | AA31: =-(U31+V31/60) -> 0 | AB31: =-(W31+X31/60) -> 0 | AC31: Dodman Island | AF31: 75 | AH31: Aerial | AJ31: Mavic 2 PRO drone aerial mapping | AK31: DroneDeploy Photogrammetry
A32: TANGO_1 Expedition | B32: DRM_10 | C32: 44990 | E32: Bruno Danis | I32: =IF(E32="","",_xlfn.LET(_xlpm.x,VLOOKUP(E32,'Drop-down_menus'!$D$2:$E$13,2,FALSE),IF(_xlpm.x=0,"",_xlpm.x))) -> https://orcid.org/0000-0002-9037-7623 | J32: =IF(F32="","",_xlfn.LET(_xlpm.x,VLOOKUP(F32,'Drop-down_menus'!$D$2:$E$13,2,FALSE),IF(_xlpm.x=0,"",_xlpm.x))) | K32: =IF(G32="","",_xlfn.LET(_xlpm.x,VLOOKUP(G32,'Drop-down_menus'!$D$2:$E$13,2,FALSE),IF(_xlpm.x=0,"",_xlpm.x))) | L32: =IF(H32="","",_xlfn.LET(_xlpm.x,VLOOKUP(H32,'Drop-down_menus'!$D$2:$E$13,2,FALSE),IF(_xlpm.x=0,"",_xlpm.x))) | M32: 0.70833333 | N32: 0.72222222 | Q32: 67 | R32: 30.3081 | S32: 67 | T32: 3.104 | Y32: =-(Q32+R32/60) -> -67.505135 | Z32: =-(S32+T32/60) -> -67.051733 | AA32: =-(U32+V32/60) -> 0 | AB32: =-(W32+X32/60) -> 0 | AC32: Blaiklock Island | AF32: 60 | AH32: Aerial | AJ32: Mavic 2 PRO drone aerial mapping | AK32: DroneDeploy Photogrammetry
A33: TANGO_1 Expedition | B33: DRM_11 | C33: 44992 | E33: Bruno Danis | I33: =IF(E33="","",_xlfn.LET(_xlpm.x,VLOOKUP(E33,'Drop-down_menus'!$D$2:$E$13,2,FALSE),IF(_xlpm.x=0,"",_xlpm.x))) -> https://orcid.org/0000-0002-9037-7623 | J33: =IF(F33="","",_xlfn.LET(_xlpm.x,VLOOKUP(F33,'Drop-down_menus'!$D$2:$E$13,2,FALSE),IF(_xlpm.x=0,"",_xlpm.x))) | K33: =IF(G33="","",_xlfn.LET(_xlpm.x,VLOOKUP(G33,'Drop-down_menus'!$D$2:$E$13,2,FALSE),IF(_xlpm.x=0,"",_xlpm.x))) | L33: =IF(H33="","",_xlfn.LET(_xlpm.x,VLOOKUP(H33,'Drop-down_menus'!$D$2:$E$13,2,FALSE),IF(_xlpm.x=0,"",_xlpm.x))) | M33: 0.46527778 | N33: 0.48611111 | Q33: 67 | R33: 30.905 | S33: 67 | T33: 5.999 | Y33: =-(Q33+R33/60) -> -67.515083 | Z33: =-(S33+T33/60) -> -67.099983 | AA33: =-(U33+V33/60) -> 0 | AB33: =-(W33+X33/60) -> 0 | AC33: Blaiklock Island | AF33: 60 | AH33: Aerial | AJ33: Mavic 2 PRO drone aerial mapping | AK33: DroneDeploy Photogrammetry
A34: TANGO_1 Expedition | B34: DRM_2 | C34: 44977 | E34: Bruno Danis | I34: =IF(E34="","",_xlfn.LET(_xlpm.x,VLOOKUP(E34,'Drop-down_menus'!$D$2:$E$13,2,FALSE),IF(_xlpm.x=0,"",_xlpm.x))) -> https://orcid.org/0000-0002-9037-7623 | J34: =IF(F34="","",_xlfn.LET(_xlpm.x,VLOOKUP(F34,'Drop-down_menus'!$D$2:$E$13,2,FALSE),IF(_xlpm.x=0,"",_xlpm.x))) | K34: =IF(G34="","",_xlfn.LET(_xlpm.x,VLOOKUP(G34,'Drop-down_menus'!$D$2:$E$13,2,FALSE),IF(_xlpm.x=0,"",_xlpm.x))) | L34: =IF(H34="","",_xlfn.LET(_xlpm.x,VLOOKUP(H34,'Drop-down_menus'!$D$2:$E$13,2,FALSE),IF(_xlpm.x=0,"",_xlpm.x))) | M34: 0.70833333 | N34: 0.73263889 | Q34: 66 | R34: 0.016 | S34: 65 | T34: 46.643 | Y34: =-(Q34+R34/60) -> -66.000267 | Z34: =-(S34+T34/60) -> -65.777383 | AA34: =-(U34+V34/60) -> 0 | AB34: =-(W34+X34/60) -> 0 | AC34: Dodman Island | AF34: 75 | AH34: Aerial | AJ34: Mavic 2 PRO drone aerial mapping | AK34: DroneDeploy Photogrammetry
A35: TANGO_1 Expedition | B35: DRM_3 | C35: 44980 | E35: Bruno Danis | I35: =IF(E35="","",_xlfn.LET(_xlpm.x,VLOOKUP(E35,'Drop-down_menus'!$D$2:$E$13,2,FALSE),IF(_xlpm.x=0,"",_xlpm.x))) -> https://orcid.org/0000-0002-9037-7623 | J35: =IF(F35="","",_xlfn.LET(_xlpm.x,VLOOKUP(F35,'Drop-down_menus'!$D$2:$E$13,2,FALSE),IF(_xlpm.x=0,"",_xlpm.x))) | K35: =IF(G35="","",_xlfn.LET(_xlpm.x,VLOOKUP(G35,'Drop-down_menus'!$D$2:$E$13,2,FALSE),IF(_xlpm.x=0,"",_xlpm.x))) | L35: =IF(H35="","",_xlfn.LET(_xlpm.x,VLOOKUP(H35,'Drop-down_menus'!$D$2:$E$13,2,FALSE),IF(_xlpm.x=0,"",_xlpm.x))) | M35: 0.69166667 | N35: 0.72847222 | Q35: 66 | R35: 0.027 | S35: 65 | T35: 46.75 | Y35: =-(Q35+R35/60) -> -66.00045 | Z35: =-(S35+T35/60) -> -65.779167 | AA35: =-(U35+V35/60) -> 0 | AB35: =-(W35+X35/60) -> 0 | AC35: Dodman Island | AF35: 75 | AH35: Aerial | AJ35: Mavic 2 PRO drone aerial mapping | AK35: DroneDeploy Photogrammetry
A36: TANGO_1 Expedition | B36: DRM_4 | C36: 44980 | E36: Bruno Danis | I36: =IF(E36="","",_xlfn.LET(_xlpm.x,VLOOKUP(E36,'Drop-down_menus'!$D$2:$E$13,2,FALSE),IF(_xlpm.x=0,"",_xlpm.x))) -> https://orcid.org/0000-0002-9037-7623 | J36: =IF(F36="","",_xlfn.LET(_xlpm.x,VLOOKUP(F36,'Drop-down_menus'!$D$2:$E$13,2,FALSE),IF(_xlpm.x=0,"",_xlpm.x))) | K36: =IF(G36="","",_xlfn.LET(_xlpm.x,VLOOKUP(G36,'Drop-down_menus'!$D$2:$E$13,2,FALSE),IF(_xlpm.x=0,"",_xlpm.x))) | L36: =IF(H36="","",_xlfn.LET(_xlpm.x,VLOOKUP(H36,'Drop-down_menus'!$D$2:$E$13,2,FALSE),IF(_xlpm.x=0,"",_xlpm.x))) | M36: 0.73888889 | N36: 0.75277778 | Q36: 66 | R36: 0.027 | S36: 65 | T36: 46.75 | Y36: =-(Q36+R36/60) -> -66.00045 | Z36: =-(S36+T36/60) -> -65.779167 | AA36: =-(U36+V36/60) -> 0 | AB36: =-(W36+X36/60) -> 0 | AC36: Dodman Island | AF36: 75 | AH36: Aerial | AJ36: Mavic 2 PRO drone aerial mapping | AK36: DroneDeploy Photogrammetry
A37: TANGO_1 Expedition | B37: DRM_5 | C37: 44988 | E37: Bruno Danis | I37: =IF(E37="","",_xlfn.LET(_xlpm.x,VLOOKUP(E37,'Drop-down_menus'!$D$2:$E$13,2,FALSE),IF(_xlpm.x=0,"",_xlpm.x))) -> https://orcid.org/0000-0002-9037-7623 | J37: =IF(F37="","",_xlfn.LET(_xlpm.x,VLOOKUP(F37,'Drop-down_menus'!$D$2:$E$13,2,FALSE),IF(_xlpm.x=0,"",_xlpm.x))) | K37: =IF(G37="","",_xlfn.LET(_xlpm.x,VLOOKUP(G37,'Drop-down_menus'!$D$2:$E$13,2,FALSE),IF(_xlpm.x=0,"",_xlpm.x))) | L37: =IF(H37="","",_xlfn.LET(_xlpm.x,VLOOKUP(H37,'Drop-down_menus'!$D$2:$E$13,2,FALSE),IF(_xlpm.x=0,"",_xlpm.x))) | M37: 0.46944444 | N37: 0.50138889 | Q37: 67 | R37: 33.112 | S37: 67 | T37: 12.89 | Y37: =-(Q37+R37/60) -> -67.551867 | Z37: =-(S37+T37/60) -> -67.214833 | AA37: =-(U37+V37/60) -> 0 | AB37: =-(W37+X37/60) -> 0 | AC37: Blaiklock Island | AF37: 60 | AH37: Aerial | AJ37: Mavic 2 PRO drone aerial mapping | AK37: DroneDeploy Photogrammetry
A38: TANGO_1 Expedition | B38: DRM_6 | C38: 44988 | E38: Bruno Danis | I38: =IF(E38="","",_xlfn.LET(_xlpm.x,VLOOKUP(E38,'Drop-down_menus'!$D$2:$E$13,2,FALSE),IF(_xlpm.x=0,"",_xlpm.x))) -> https://orcid.org/0000-0002-9037-7623 | J38: =IF(F38="","",_xlfn.LET(_xlpm.x,VLOOKUP(F38,'Drop-down_menus'!$D$2:$E$13,2,FALSE),IF(_xlpm.x=0,"",_xlpm.x))) | K38: =IF(G38="","",_xlfn.LET(_xlpm.x,VLOOKUP(G38,'Drop-down_menus'!$D$2:$E$13,2,FALSE),IF(_xlpm.x=0,"",_xlpm.x))) | L38: =IF(H38="","",_xlfn.LET(_xlpm.x,VLOOKUP(H38,'Drop-down_menus'!$D$2:$E$13,2,FALSE),IF(_xlpm.x=0,"",_xlpm.x))) | M38: 0.34722222 | N38: 0.39583333 | Q38: 67 | R38: 33.112 | S38: 67 | T38: 12.89 | Y38: =-(Q38+R38/60) -> -67.551867 | Z38: =-(S38+T38/60) -> -67.214833 | AA38: =-(U38+V38/60) -> 0 | AB38: =-(W38+X38/60) -> 0 | AC38: Blaiklock Island | AF38: 60 | AH38: Aerial | AJ38: Mavic 2 PRO drone aerial mapping | AK38: DroneDeploy Photogrammetry
A39: TANGO_1 Expedition | B39: DRM_7 | C39: 44989 | E39: Bruno Danis | I39: =IF(E39="","",_xlfn.LET(_xlpm.x,VLOOKUP(E39,'Drop-down_menus'!$D$2:$E$13,2,FALSE),IF(_xlpm.x=0,"",_xlpm.x))) -> https://orcid.org/0000-0002-9037-7623 | J39: =IF(F39="","",_xlfn.LET(_xlpm.x,VLOOKUP(F39,'Drop-down_menus'!$D$2:$E$13,2,FALSE),IF(_xlpm.x=0,"",_xlpm.x))) | K39: =IF(G39="","",_xlfn.LET(_xlpm.x,VLOOKUP(G39,'Drop-down_menus'!$D$2:$E$13,2,FALSE),IF(_xlpm.x=0,"",_xlpm.x))) | L39: =IF(H39="","",_xlfn.LET(_xlpm.x,VLOOKUP(H39,'Drop-down_menus'!$D$2:$E$13,2,FALSE),IF(_xlpm.x=0,"",_xlpm.x))) | M39: 0.72222222 | N39: 0.76041667 | Q39: 67 | R39: 33.112 | S39: 67 | T39: 12.89 | Y39: =-(Q39+R39/60) -> -67.551867 | Z39: =-(S39+T39/60) -> -67.214833 | AA39: =-(U39+V39/60) -> 0 | AB39: =-(W39+X39/60) -> 0 | AC39: Blaiklock Island | AF39: 60 | AH39: Aerial | AJ39: Mavic 2 PRO drone aerial mapping | AK39: DroneDeploy Photogrammetry
A40: TANGO_1 Expedition | B40: DRM_8 | C40: 44989 | E40: Bruno Danis | I40: =IF(E40="","",_xlfn.LET(_xlpm.x,VLOOKUP(E40,'Drop-down_menus'!$D$2:$E$13,2,FALSE),IF(_xlpm.x=0,"",_xlpm.x))) -> https://orcid.org/0000-0002-9037-7623 | J40: =IF(F40="","",_xlfn.LET(_xlpm.x,VLOOKUP(F40,'Drop-down_menus'!$D$2:$E$13,2,FALSE),IF(_xlpm.x=0,"",_xlpm.x))) | K40: =IF(G40="","",_xlfn.LET(_xlpm.x,VLOOKUP(G40,'Drop-down_menus'!$D$2:$E$13,2,FALSE),IF(_xlpm.x=0,"",_xlpm.x))) | L40: =IF(H40="","",_xlfn.LET(_xlpm.x,VLOOKUP(H40,'Drop-down_menus'!$D$2:$E$13,2,FALSE),IF(_xlpm.x=0,"",_xlpm.x))) | M40: 0.45833333 | N40: 0.47222222 | Q40: 67 | R40: 32.994 | S40: 67 | T40: 14.838 | Y40: =-(Q40+R40/60) -> -67.5499 | Z40: =-(S40+T40/60) -> -67.2473 | AA40: =-(U40+V40/60) -> 0 | AB40: =-(W40+X40/60) -> 0 | AC40: Blaiklock Island | AF40: 60 | AH40: Aerial | AJ40: Mavic 2 PRO drone aerial mapping | AK40: DroneDeploy Photogrammetry
...

Sheet Samples
A1: parentSampleID | B1: sampleID | C1: eventID | D1: eventIDinEvents | E1: Sample Type | F1: Parameter | G1: verbatimIdentification | H1: vernacularName | I1: correctedVerbatimIdentification | J1: scientificName | K1: identificationQualifier | L1: scientificNameID | M1: scientificNameAuthorship | N1: kingdom | O1: phylum | P1: class | Q1: order | R1: family | S1: genus | T1: specificEpithet | U1: individualCount | V1: identifiedBy1 | W1: identifiedBy2 | X1: identifiedBy3 | Y1: identifiedByID1 | Z1: identifiedByID2 | AA1: identifiedByID3 | AB1: preserved in | AC1: container | AD1: Remark | AE1: recordedBy1 | AF1: recordedBy2 | AG1: recordedByID1 | AH1: recordedByID2 | AI1: occurrenceRemarks
B2: 1 | C2: DR_1 | D2: =COUNTIF(Events!$B$2:$B$171, C2) > 0 -> TRUE | E2: Media_file | F2: Aerial Imagery | J2: =IF(I2="","",_xlfn.LET(_xlpm.x,VLOOKUP(I2,'2026-01-09_taxon-match'!$A$2:$N$81,4,FALSE),IF(_xlpm.x=0,"",_xlpm.x))) | L2: =IF(I2="","",_xlfn.LET(_xlpm.x,VLOOKUP(I2,'2026-01-09_taxon-match'!$A$2:$N$81,3,FALSE),IF(_xlpm.x=0,"",_xlpm.x))) | M2: =IF($I2="","",_xlfn.LET(_xlpm.x,VLOOKUP($I2,'2026-01-09_taxon-match'!$A$2:$N$81,5,FALSE),IF(_xlpm.x=0,"",_xlpm.x))) | N2: =IF($I2="","",_xlfn.LET(_xlpm.x,VLOOKUP($I2,'2026-01-09_taxon-match'!$A$2:$N$81,6,FALSE),IF(_xlpm.x=0,"",_xlpm.x))) | O2: =IF($I2="","",_xlfn.LET(_xlpm.x,VLOOKUP($I2,'2026-01-09_taxon-match'!$A$2:$N$81,8,FALSE),IF(_xlpm.x=0,"",_xlpm.x))) | P2: =IF($I2="","",_xlfn.LET(_xlpm.x,VLOOKUP($I2,'2026-01-09_taxon-match'!$A$2:$N$81,8,FALSE),IF(_xlpm.x=0,"",_xlpm.x))) | Q2: =IF($I2="","",_xlfn.LET(_xlpm.x,VLOOKUP($I2,'2026-01-09_taxon-match'!$A$2:$N$81,9,FALSE),IF(_xlpm.x=0,"",_xlpm.x))) | R2: =IF($I2="","",_xlfn.LET(_xlpm.x,VLOOKUP($I2,'2026-01-09_taxon-match'!$A$2:$N$81,10,FALSE),IF(_xlpm.x=0,"",_xlpm.x))) | S2: =IF($I2="","",_xlfn.LET(_xlpm.x,VLOOKUP($I2,'2026-01-09_taxon-match'!$A$2:$N$81,11,FALSE),IF(_xlpm.x=0,"",_xlpm.x))) | T2: =IF($I2="","",_xlfn.LET(_xlpm.x,VLOOKUP($I2,'2026-01-09_taxon-match'!$A$2:$N$81,13,FALSE),IF(_xlpm.x=0,"",_xlpm.x))) | V2: Bruno Danis | Y2: =IF(V2="","",_xlfn.LET(_xlpm.x,VLOOKUP(V2,'Drop-down_menus'!$D$2:$E$13,2,FALSE),IF(_xlpm.x=0,"",_xlpm.x))) -> https://orcid.org/0000-0002-9037-7623 | Z2: =IF(W2="","",_xlfn.LET(_xlpm.x,VLOOKUP(W2,'Drop-down_menus'!$D$2:$E$13,2,FALSE),IF(_xlpm.x=0,"",_xlpm.x))) | AA2: =IF(X2="","",_xlfn.LET(_xlpm.x,VLOOKUP(X2,'Drop-down_menus'!$D$2:$E$13,2,FALSE),IF(_xlpm.x=0,"",_xlpm.x))) | AC2: image files | AE2: Bruno Danis | AF2: Henri Robert | AG2: =IF(AE2="","",_xlfn.LET(_xlpm.x,VLOOKUP(AE2,'Drop-down_menus'!$D$2:$E$13,2,FALSE),IF(_xlpm.x=0,"",_xlpm.x))) -> https://orcid.org/0000-0002-9037-7623 | AH2: =IF(AF2="","",_xlfn.LET(_xlpm.x,VLOOKUP(AF2,'Drop-down_menus'!$D$2:$E$13,2,FALSE),IF(_xlpm.x=0,"",_xlpm.x)))
B3: 2 | C3: ROV_1 | D3: =COUNTIF(Events!$B$2:$B$171, C3) > 0 -> TRUE | E3: Media_folder | F3: Mapping Quadrat | J3: =IF(I3="","",_xlfn.LET(_xlpm.x,VLOOKUP(I3,'2026-01-09_taxon-match'!$A$2:$N$81,4,FALSE),IF(_xlpm.x=0,"",_xlpm.x))) | L3: =IF(I3="","",_xlfn.LET(_xlpm.x,VLOOKUP(I3,'2026-01-09_taxon-match'!$A$2:$N$81,3,FALSE),IF(_xlpm.x=0,"",_xlpm.x))) | M3: =IF($I3="","",_xlfn.LET(_xlpm.x,VLOOKUP($I3,'2026-01-09_taxon-match'!$A$2:$N$81,5,FALSE),IF(_xlpm.x=0,"",_xlpm.x))) | N3: =IF($I3="","",_xlfn.LET(_xlpm.x,VLOOKUP($I3,'2026-01-09_taxon-match'!$A$2:$N$81,6,FALSE),IF(_xlpm.x=0,"",_xlpm.x))) | O3: =IF($I3="","",_xlfn.LET(_xlpm.x,VLOOKUP($I3,'2026-01-09_taxon-match'!$A$2:$N$81,7,FALSE),IF(_xlpm.x=0,"",_xlpm.x))) | P3: =IF($I3="","",_xlfn.LET(_xlpm.x,VLOOKUP($I3,'2026-01-09_taxon-match'!$A$2:$N$81,8,FALSE),IF(_xlpm.x=0,"",_xlpm.x))) | Q3: =IF($I3="","",_xlfn.LET(_xlpm.x,VLOOKUP($I3,'2026-01-09_taxon-match'!$A$2:$N$81,9,FALSE),IF(_xlpm.x=0,"",_xlpm.x))) | R3: =IF($I3="","",_xlfn.LET(_xlpm.x,VLOOKUP($I3,'2026-01-09_taxon-match'!$A$2:$N$81,10,FALSE),IF(_xlpm.x=0,"",_xlpm.x))) | S3: =IF($I3="","",_xlfn.LET(_xlpm.x,VLOOKUP($I3,'2026-01-09_taxon-match'!$A$2:$N$81,11,FALSE),IF(_xlpm.x=0,"",_xlpm.x))) | T3: =IF($I3="","",_xlfn.LET(_xlpm.x,VLOOKUP($I3,'2026-01-09_taxon-match'!$A$2:$N$81,13,FALSE),IF(_xlpm.x=0,"",_xlpm.x))) | Y3: =IF(V3="","",_xlfn.LET(_xlpm.x,VLOOKUP(V3,'Drop-down_menus'!$D$2:$E$13,2,FALSE),IF(_xlpm.x=0,"",_xlpm.x))) | Z3: =IF(W3="","",_xlfn.LET(_xlpm.x,VLOOKUP(W3,'Drop-down_menus'!$D$2:$E$13,2,FALSE),IF(_xlpm.x=0,"",_xlpm.x))) | AA3: =IF(X3="","",_xlfn.LET(_xlpm.x,VLOOKUP(X3,'Drop-down_menus'!$D$2:$E$13,2,FALSE),IF(_xlpm.x=0,"",_xlpm.x))) | AC3: Folder | AD3: Pool 4 | AE3: Bruno Danis | AF3: Henri Robert | AG3: =IF(AE3="","",_xlfn.LET(_xlpm.x,VLOOKUP(AE3,'Drop-down_menus'!$D$2:$E$13,2,FALSE),IF(_xlpm.x=0,"",_xlpm.x))) -> https://orcid.org/0000-0002-9037-7623 | AH3: =IF(AF3="","",_xlfn.LET(_xlpm.x,VLOOKUP(AF3,'Drop-down_menus'!$D$2:$E$13,2,FALSE),IF(_xlpm.x=0,"",_xlpm.x)))
B4: 3 | C4: ROV_2 | D4: =COUNTIF(Events!$B$2:$B$171, C4) > 0 -> TRUE | E4: Media_folder | F4: Mapping Quadrat | J4: =IF(I4="","",_xlfn.LET(_xlpm.x,VLOOKUP(I4,'2026-01-09_taxon-match'!$A$2:$N$81,4,FALSE),IF(_xlpm.x=0,"",_xlpm.x))) | L4: =IF(I4="","",_xlfn.LET(_xlpm.x,VLOOKUP(I4,'2026-01-09_taxon-match'!$A$2:$N$81,3,FALSE),IF(_xlpm.x=0,"",_xlpm.x))) | M4: =IF($I4="","",_xlfn.LET(_xlpm.x,VLOOKUP($I4,'2026-01-09_taxon-match'!$A$2:$N$81,5,FALSE),IF(_xlpm.x=0,"",_xlpm.x))) | N4: =IF($I4="","",_xlfn.LET(_xlpm.x,VLOOKUP($I4,'2026-01-09_taxon-match'!$A$2:$N$81,6,FALSE),IF(_xlpm.x=0,"",_xlpm.x))) | O4: =IF($I4="","",_xlfn.LET(_xlpm.x,VLOOKUP($I4,'2026-01-09_taxon-match'!$A$2:$N$81,7,FALSE),IF(_xlpm.x=0,"",_xlpm.x))) | P4: =IF($I4="","",_xlfn.LET(_xlpm.x,VLOOKUP($I4,'2026-01-09_taxon-match'!$A$2:$N$81,8,FALSE),IF(_xlpm.x=0,"",_xlpm.x))) | Q4: =IF($I4="","",_xlfn.LET(_xlpm.x,VLOOKUP($I4,'2026-01-09_taxon-match'!$A$2:$N$81,9,FALSE),IF(_xlpm.x=0,"",_xlpm.x))) | R4: =IF($I4="","",_xlfn.LET(_xlpm.x,VLOOKUP($I4,'2026-01-09_taxon-match'!$A$2:$N$81,10,FALSE),IF(_xlpm.x=0,"",_xlpm.x))) | S4: =IF($I4="","",_xlfn.LET(_xlpm.x,VLOOKUP($I4,'2026-01-09_taxon-match'!$A$2:$N$81,11,FALSE),IF(_xlpm.x=0,"",_xlpm.x))) | T4: =IF($I4="","",_xlfn.LET(_xlpm.x,VLOOKUP($I4,'2026-01-09_taxon-match'!$A$2:$N$81,13,FALSE),IF(_xlpm.x=0,"",_xlpm.x))) | V4: Bruno Danis | W4: Lea Katz | Y4: =IF(V4="","",_xlfn.LET(_xlpm.x,VLOOKUP(V4,'Drop-down_menus'!$D$2:$E$13,2,FALSE),IF(_xlpm.x=0,"",_xlpm.x))) -> https://orcid.org/0000-0002-9037-7623 | Z4: =IF(W4="","",_xlfn.LET(_xlpm.x,VLOOKUP(W4,'Drop-down_menus'!$D$2:$E$13,2,FALSE),IF(_xlpm.x=0,"",_xlpm.x))) -> https://orcid.org/0000-0001-5748-602X | AA4: =IF(X4="","",_xlfn.LET(_xlpm.x,VLOOKUP(X4,'Drop-down_menus'!$D$2:$E$13,2,FALSE),IF(_xlpm.x=0,"",_xlpm.x))) | AC4: Folder | AD4: Pool 4 | AE4: Bruno Danis | AF4: Henri Robert | AG4: =IF(AE4="","",_xlfn.LET(_xlpm.x,VLOOKUP(AE4,'Drop-down_menus'!$D$2:$E$13,2,FALSE),IF(_xlpm.x=0,"",_xlpm.x))) -> https://orcid.org/0000-0002-9037-7623 | AH4: =IF(AF4="","",_xlfn.LET(_xlpm.x,VLOOKUP(AF4,'Drop-down_menus'!$D$2:$E$13,2,FALSE),IF(_xlpm.x=0,"",_xlpm.x)))
B5: 4 | C5: ROV_2 | D5: =COUNTIF(Events!$B$2:$B$171, C5) > 0 -> TRUE | E5: Media_folder | F5: Mapping Transect | J5: =IF(I5="","",_xlfn.LET(_xlpm.x,VLOOKUP(I5,'2026-01-09_taxon-match'!$A$2:$N$81,4,FALSE),IF(_xlpm.x=0,"",_xlpm.x))) | L5: =IF(I5="","",_xlfn.LET(_xlpm.x,VLOOKUP(I5,'2026-01-09_taxon-match'!$A$2:$N$81,3,FALSE),IF(_xlpm.x=0,"",_xlpm.x))) | M5: =IF($I5="","",_xlfn.LET(_xlpm.x,VLOOKUP($I5,'2026-01-09_taxon-match'!$A$2:$N$81,5,FALSE),IF(_xlpm.x=0,"",_xlpm.x))) | N5: =IF($I5="","",_xlfn.LET(_xlpm.x,VLOOKUP($I5,'2026-01-09_taxon-match'!$A$2:$N$81,6,FALSE),IF(_xlpm.x=0,"",_xlpm.x))) | O5: =IF($I5="","",_xlfn.LET(_xlpm.x,VLOOKUP($I5,'2026-01-09_taxon-match'!$A$2:$N$81,7,FALSE),IF(_xlpm.x=0,"",_xlpm.x))) | P5: =IF($I5="","",_xlfn.LET(_xlpm.x,VLOOKUP($I5,'2026-01-09_taxon-match'!$A$2:$N$81,8,FALSE),IF(_xlpm.x=0,"",_xlpm.x))) | Q5: =IF($I5="","",_xlfn.LET(_xlpm.x,VLOOKUP($I5,'2026-01-09_taxon-match'!$A$2:$N$81,9,FALSE),IF(_xlpm.x=0,"",_xlpm.x))) | R5: =IF($I5="","",_xlfn.LET(_xlpm.x,VLOOKUP($I5,'2026-01-09_taxon-match'!$A$2:$N$81,10,FALSE),IF(_xlpm.x=0,"",_xlpm.x))) | S5: =IF($I5="","",_xlfn.LET(_xlpm.x,VLOOKUP($I5,'2026-01-09_taxon-match'!$A$2:$N$81,11,FALSE),IF(_xlpm.x=0,"",_xlpm.x))) | T5: =IF($I5="","",_xlfn.LET(_xlpm.x,VLOOKUP($I5,'2026-01-09_taxon-match'!$A$2:$N$81,13,FALSE),IF(_xlpm.x=0,"",_xlpm.x))) | V5: Bruno Danis | W5: Lea Katz | Y5: =IF(V5="","",_xlfn.LET(_xlpm.x,VLOOKUP(V5,'Drop-down_menus'!$D$2:$E$13,2,FALSE),IF(_xlpm.x=0,"",_xlpm.x))) -> https://orcid.org/0000-0002-9037-7623 | Z5: =IF(W5="","",_xlfn.LET(_xlpm.x,VLOOKUP(W5,'Drop-down_menus'!$D$2:$E$13,2,FALSE),IF(_xlpm.x=0,"",_xlpm.x))) -> https://orcid.org/0000-0001-5748-602X | AA5: =IF(X5="","",_xlfn.LET(_xlpm.x,VLOOKUP(X5,'Drop-down_menus'!$D$2:$E$13,2,FALSE),IF(_xlpm.x=0,"",_xlpm.x))) | AC5: Folder | AD5: Pool 4 | AE5: Bruno Danis | AF5: Henri Robert | AG5: =IF(AE5="","",_xlfn.LET(_xlpm.x,VLOOKUP(AE5,'Drop-down_menus'!$D$2:$E$13,2,FALSE),IF(_xlpm.x=0,"",_xlpm.x))) -> https://orcid.org/0000-0002-9037-7623 | AH5: =IF(AF5="","",_xlfn.LET(_xlpm.x,VLOOKUP(AF5,'Drop-down_menus'!$D$2:$E$13,2,FALSE),IF(_xlpm.x=0,"",_xlpm.x)))
B6: 5 | C6: ROV_3 | D6: =COUNTIF(Events!$B$2:$B$171, C6) > 0 -> TRUE | E6: Media_folder | F6: Mapping Transect | J6: =IF(I6="","",_xlfn.LET(_xlpm.x,VLOOKUP(I6,'2026-01-09_taxon-match'!$A$2:$N$81,4,FALSE),IF(_xlpm.x=0,"",_xlpm.x))) | L6: =IF(I6="","",_xlfn.LET(_xlpm.x,VLOOKUP(I6,'2026-01-09_taxon-match'!$A$2:$N$81,3,FALSE),IF(_xlpm.x=0,"",_xlpm.x))) | M6: =IF($I6="","",_xlfn.LET(_xlpm.x,VLOOKUP($I6,'2026-01-09_taxon-match'!$A$2:$N$81,5,FALSE),IF(_xlpm.x=0,"",_xlpm.x))) | N6: =IF($I6="","",_xlfn.LET(_xlpm.x,VLOOKUP($I6,'2026-01-09_taxon-match'!$A$2:$N$81,6,FALSE),IF(_xlpm.x=0,"",_xlpm.x))) | O6: =IF($I6="","",_xlfn.LET(_xlpm.x,VLOOKUP($I6,'2026-01-09_taxon-match'!$A$2:$N$81,7,FALSE),IF(_xlpm.x=0,"",_xlpm.x))) | P6: =IF($I6="","",_xlfn.LET(_xlpm.x,VLOOKUP($I6,'2026-01-09_taxon-match'!$A$2:$N$81,8,FALSE),IF(_xlpm.x=0,"",_xlpm.x))) | Q6: =IF($I6="","",_xlfn.LET(_xlpm.x,VLOOKUP($I6,'2026-01-09_taxon-match'!$A$2:$N$81,9,FALSE),IF(_xlpm.x=0,"",_xlpm.x))) | R6: =IF($I6="","",_xlfn.LET(_xlpm.x,VLOOKUP($I6,'2026-01-09_taxon-match'!$A$2:$N$81,10,FALSE),IF(_xlpm.x=0,"",_xlpm.x))) | S6: =IF($I6="","",_xlfn.LET(_xlpm.x,VLOOKUP($I6,'2026-01-09_taxon-match'!$A$2:$N$81,11,FALSE),IF(_xlpm.x=0,"",_xlpm.x))) | T6: =IF($I6="","",_xlfn.LET(_xlpm.x,VLOOKUP($I6,'2026-01-09_taxon-match'!$A$2:$N$81,13,FALSE),IF(_xlpm.x=0,"",_xlpm.x))) | V6: Bruno Danis | W6: Lea Katz | Y6: =IF(V6="","",_xlfn.LET(_xlpm.x,VLOOKUP(V6,'Drop-down_menus'!$D$2:$E$13,2,FALSE),IF(_xlpm.x=0,"",_xlpm.x))) -> https://orcid.org/0000-0002-9037-7623 | Z6: =IF(W6="","",_xlfn.LET(_xlpm.x,VLOOKUP(W6,'Drop-down_menus'!$D$2:$E$13,2,FALSE),IF(_xlpm.x=0,"",_xlpm.x))) -> https://orcid.org/0000-0001-5748-602X | AA6: =IF(X6="","",_xlfn.LET(_xlpm.x,VLOOKUP(X6,'Drop-down_menus'!$D$2:$E$13,2,FALSE),IF(_xlpm.x=0,"",_xlpm.x))) | AC6: Folder | AD6: Pool 4 | AE6: Bruno Danis | AF6: Henri Robert | AG6: =IF(AE6="","",_xlfn.LET(_xlpm.x,VLOOKUP(AE6,'Drop-down_menus'!$D$2:$E$13,2,FALSE),IF(_xlpm.x=0,"",_xlpm.x))) -> https://orcid.org/0000-0002-9037-7623 | AH6: =IF(AF6="","",_xlfn.LET(_xlpm.x,VLOOKUP(AF6,'Drop-down_menus'!$D$2:$E$13,2,FALSE),IF(_xlpm.x=0,"",_xlpm.x)))
B7: 6 | C7: CTD_1 | D7: =COUNTIF(Events!$B$2:$B$171, C7) > 0 -> TRUE | E7: Media_file | F7: Conductivity - Salinity - Depth | J7: =IF(I7="","",_xlfn.LET(_xlpm.x,VLOOKUP(I7,'2026-01-09_taxon-match'!$A$2:$N$81,4,FALSE),IF(_xlpm.x=0,"",_xlpm.x))) | L7: =IF(I7="","",_xlfn.LET(_xlpm.x,VLOOKUP(I7,'2026-01-09_taxon-match'!$A$2:$N$81,3,FALSE),IF(_xlpm.x=0,"",_xlpm.x))) | M7: =IF($I7="","",_xlfn.LET(_xlpm.x,VLOOKUP($I7,'2026-01-09_taxon-match'!$A$2:$N$81,5,FALSE),IF(_xlpm.x=0,"",_xlpm.x))) | N7: =IF($I7="","",_xlfn.LET(_xlpm.x,VLOOKUP($I7,'2026-01-09_taxon-match'!$A$2:$N$81,6,FALSE),IF(_xlpm.x=0,"",_xlpm.x))) | O7: =IF($I7="","",_xlfn.LET(_xlpm.x,VLOOKUP($I7,'2026-01-09_taxon-match'!$A$2:$N$81,7,FALSE),IF(_xlpm.x=0,"",_xlpm.x))) | P7: =IF($I7="","",_xlfn.LET(_xlpm.x,VLOOKUP($I7,'2026-01-09_taxon-match'!$A$2:$N$81,8,FALSE),IF(_xlpm.x=0,"",_xlpm.x))) | Q7: =IF($I7="","",_xlfn.LET(_xlpm.x,VLOOKUP($I7,'2026-01-09_taxon-match'!$A$2:$N$81,9,FALSE),IF(_xlpm.x=0,"",_xlpm.x))) | R7: =IF($I7="","",_xlfn.LET(_xlpm.x,VLOOKUP($I7,'2026-01-09_taxon-match'!$A$2:$N$81,10,FALSE),IF(_xlpm.x=0,"",_xlpm.x))) | S7: =IF($I7="","",_xlfn.LET(_xlpm.x,VLOOKUP($I7,'2026-01-09_taxon-match'!$A$2:$N$81,11,FALSE),IF(_xlpm.x=0,"",_xlpm.x))) | T7: =IF($I7="","",_xlfn.LET(_xlpm.x,VLOOKUP($I7,'2026-01-09_taxon-match'!$A$2:$N$81,13,FALSE),IF(_xlpm.x=0,"",_xlpm.x))) | Y7: =IF(V7="","",_xlfn.LET(_xlpm.x,VLOOKUP(V7,'Drop-down_menus'!$D$2:$E$13,2,FALSE),IF(_xlpm.x=0,"",_xlpm.x))) | Z7: =IF(W7="","",_xlfn.LET(_xlpm.x,VLOOKUP(W7,'Drop-down_menus'!$D$2:$E$13,2,FALSE),IF(_xlpm.x=0,"",_xlpm.x))) | AA7: =IF(X7="","",_xlfn.LET(_xlpm.x,VLOOKUP(X7,'Drop-down_menus'!$D$2:$E$13,2,FALSE),IF(_xlpm.x=0,"",_xlpm.x))) | AE7: Bruno Danis | AF7: Henri Robert | AG7: =IF(AE7="","",_xlfn.LET(_xlpm.x,VLOOKUP(AE7,'Drop-down_menus'!$D$2:$E$13,2,FALSE),IF(_xlpm.x=0,"",_xlpm.x))) -> https://orcid.org/0000-0002-9037-7623 | AH7: =IF(AF7="","",_xlfn.LET(_xlpm.x,VLOOKUP(AF7,'Drop-down_menus'!$D$2:$E$13,2,FALSE),IF(_xlpm.x=0,"",_xlpm.x)))
B8: 7 | C8: RD_1 | D8: =COUNTIF(Events!$B$2:$B$171, C8) > 0 -> TRUE | E8: Individual | F8: Biodiversity | G8: Invertebrates | I8: Animalia | J8: =IF(I8="","",_xlfn.LET(_xlpm.x,VLOOKUP(I8,'2026-01-09_taxon-match'!$A$2:$N$81,4,FALSE),IF(_xlpm.x=0,"",_xlpm.x))) -> Animalia | L8: =IF(I8="","",_xlfn.LET(_xlpm.x,VLOOKUP(I8,'2026-01-09_taxon-match'!$A$2:$N$81,3,FALSE),IF(_xlpm.x=0,"",_xlpm.x))) -> urn:lsid:marinespecies.org:taxname:2 | M8: =IF($I8="","",_xlfn.LET(_xlpm.x,VLOOKUP($I8,'2026-01-09_taxon-match'!$A$2:$N$81,5,FALSE),IF(_xlpm.x=0,"",_xlpm.x))) | N8: =IF($I8="","",_xlfn.LET(_xlpm.x,VLOOKUP($I8,'2026-01-09_taxon-match'!$A$2:$N$81,6,FALSE),IF(_xlpm.x=0,"",_xlpm.x))) -> Animalia | O8: =IF($I8="","",_xlfn.LET(_xlpm.x,VLOOKUP($I8,'2026-01-09_taxon-match'!$A$2:$N$81,7,FALSE),IF(_xlpm.x=0,"",_xlpm.x))) | P8: =IF($I8="","",_xlfn.LET(_xlpm.x,VLOOKUP($I8,'2026-01-09_taxon-match'!$A$2:$N$81,8,FALSE),IF(_xlpm.x=0,"",_xlpm.x))) | Q8: =IF($I8="","",_xlfn.LET(_xlpm.x,VLOOKUP($I8,'2026-01-09_taxon-match'!$A$2:$N$81,9,FALSE),IF(_xlpm.x=0,"",_xlpm.x))) | R8: =IF($I8="","",_xlfn.LET(_xlpm.x,VLOOKUP($I8,'2026-01-09_taxon-match'!$A$2:$N$81,10,FALSE),IF(_xlpm.x=0,"",_xlpm.x))) | S8: =IF($I8="","",_xlfn.LET(_xlpm.x,VLOOKUP($I8,'2026-01-09_taxon-match'!$A$2:$N$81,11,FALSE),IF(_xlpm.x=0,"",_xlpm.x))) | T8: =IF($I8="","",_xlfn.LET(_xlpm.x,VLOOKUP($I8,'2026-01-09_taxon-match'!$A$2:$N$81,13,FALSE),IF(_xlpm.x=0,"",_xlpm.x))) | U8: 4 | V8: Henri Robert | W8: Camille Moreau | Y8: =IF(V8="","",_xlfn.LET(_xlpm.x,VLOOKUP(V8,'Drop-down_menus'!$D$2:$E$13,2,FALSE),IF(_xlpm.x=0,"",_xlpm.x))) | Z8: =IF(W8="","",_xlfn.LET(_xlpm.x,VLOOKUP(W8,'Drop-down_menus'!$D$2:$E$13,2,FALSE),IF(_xlpm.x=0,"",_xlpm.x))) -> https://orcid.org/0000-0002-0981-7442 | AA8: =IF(X8="","",_xlfn.LET(_xlpm.x,VLOOKUP(X8,'Drop-down_menus'!$D$2:$E$13,2,FALSE),IF(_xlpm.x=0,"",_xlpm.x))) | AB8: EtOH 70 | AC8: Kautex 500 ml | AE8: Bruno Danis | AF8: Henri Robert | AG8: =IF(AE8="","",_xlfn.LET(_xlpm.x,VLOOKUP(AE8,'Drop-down_menus'!$D$2:$E$13,2,FALSE),IF(_xlpm.x=0,"",_xlpm.x))) -> https://orcid.org/0000-0002-9037-7623 | AH8: =IF(AF8="","",_xlfn.LET(_xlpm.x,VLOOKUP(AF8,'Drop-down_menus'!$D$2:$E$13,2,FALSE),IF(_xlpm.x=0,"",_xlpm.x)))
B9: 8 | C9: RD_1 | D9: =COUNTIF(Events!$B$2:$B$171, C9) > 0 -> TRUE | E9: Individual | F9: Biodiversity | G9: Invertebrates | I9: Animalia | J9: =IF(I9="","",_xlfn.LET(_xlpm.x,VLOOKUP(I9,'2026-01-09_taxon-match'!$A$2:$N$81,4,FALSE),IF(_xlpm.x=0,"",_xlpm.x))) -> Animalia | L9: =IF(I9="","",_xlfn.LET(_xlpm.x,VLOOKUP(I9,'2026-01-09_taxon-match'!$A$2:$N$81,3,FALSE),IF(_xlpm.x=0,"",_xlpm.x))) -> urn:lsid:marinespecies.org:taxname:2 | M9: =IF($I9="","",_xlfn.LET(_xlpm.x,VLOOKUP($I9,'2026-01-09_taxon-match'!$A$2:$N$81,5,FALSE),IF(_xlpm.x=0,"",_xlpm.x))) | N9: =IF($I9="","",_xlfn.LET(_xlpm.x,VLOOKUP($I9,'2026-01-09_taxon-match'!$A$2:$N$81,6,FALSE),IF(_xlpm.x=0,"",_xlpm.x))) -> Animalia | O9: =IF($I9="","",_xlfn.LET(_xlpm.x,VLOOKUP($I9,'2026-01-09_taxon-match'!$A$2:$N$81,7,FALSE),IF(_xlpm.x=0,"",_xlpm.x))) | P9: =IF($I9="","",_xlfn.LET(_xlpm.x,VLOOKUP($I9,'2026-01-09_taxon-match'!$A$2:$N$81,8,FALSE),IF(_xlpm.x=0,"",_xlpm.x))) | Q9: =IF($I9="","",_xlfn.LET(_xlpm.x,VLOOKUP($I9,'2026-01-09_taxon-match'!$A$2:$N$81,9,FALSE),IF(_xlpm.x=0,"",_xlpm.x))) | R9: =IF($I9="","",_xlfn.LET(_xlpm.x,VLOOKUP($I9,'2026-01-09_taxon-match'!$A$2:$N$81,10,FALSE),IF(_xlpm.x=0,"",_xlpm.x))) | S9: =IF($I9="","",_xlfn.LET(_xlpm.x,VLOOKUP($I9,'2026-01-09_taxon-match'!$A$2:$N$81,11,FALSE),IF(_xlpm.x=0,"",_xlpm.x))) | T9: =IF($I9="","",_xlfn.LET(_xlpm.x,VLOOKUP($I9,'2026-01-09_taxon-match'!$A$2:$N$81,13,FALSE),IF(_xlpm.x=0,"",_xlpm.x))) | U9: 500 | V9: Henri Robert | W9: Camille Moreau | Y9: =IF(V9="","",_xlfn.LET(_xlpm.x,VLOOKUP(V9,'Drop-down_menus'!$D$2:$E$13,2,FALSE),IF(_xlpm.x=0,"",_xlpm.x))) | Z9: =IF(W9="","",_xlfn.LET(_xlpm.x,VLOOKUP(W9,'Drop-down_menus'!$D$2:$E$13,2,FALSE),IF(_xlpm.x=0,"",_xlpm.x))) -> https://orcid.org/0000-0002-0981-7442 | AA9: =IF(X9="","",_xlfn.LET(_xlpm.x,VLOOKUP(X9,'Drop-down_menus'!$D$2:$E$13,2,FALSE),IF(_xlpm.x=0,"",_xlpm.x))) | AB9: EtOH | AC9: Kautex 100 ml | AE9: Bruno Danis | AF9: Henri Robert | AG9: =IF(AE9="","",_xlfn.LET(_xlpm.x,VLOOKUP(AE9,'Drop-down_menus'!$D$2:$E$13,2,FALSE),IF(_xlpm.x=0,"",_xlpm.x))) -> https://orcid.org/0000-0002-9037-7623 | AH9: =IF(AF9="","",_xlfn.LET(_xlpm.x,VLOOKUP(AF9,'Drop-down_menus'!$D$2:$E$13,2,FALSE),IF(_xlpm.x=0,"",_xlpm.x)))
