Workbook

Sheet STATS_Digest
A1: Cumulative time for deployments | B1: =STATS!B1 -> #REF! | D1: Number of events per gear | E1: =STATS!J3 -> AT | F1: =STATS!K3 -> 5 | H1: Data Mass (GB) | I1: =SUM(I2:I8) -> 523.23
A2: Number of Events | B2: =STATS!F1 -> 178 | E2: =STATS!J4 -> BATHY | F2: 5 | H2: ROV_frontCAM
A3: Number of Samples | B3: =STATS!F2 -> 3952 | E3: =STATS!J5 -> CTD | F3: =STATS!K5 -> 13 | H3: ROV_GoPRO | I3: 425
A4: Fuel consumption | E4: =STATS!J6 -> CYANO | F4: =STATS!K6 -> 5 | H4: MAVIC2_Bruno | I4: =67+0.97+3.74+2.8+4.25+1.61+3.4+4.2+1.03+1.67+0.78+2.93+1.43+0.08+0.78+0.84+0.48+0.24 -> 98.23
A5: Area covered | E5: =STATS!J2 -> DR | F5: =STATS!K2 -> 5 | H5: Photos
E6: =STATS!J7 -> DRM | F6: =STATS!K7 -> 11 | H6: Videos
E7: =STATS!J8 -> ICE | F7: =STATS!K8 -> 0 | H7: CTD data
E8: =STATS!J9 -> ITD | F8: =STATS!K9 -> 3 | H8: Incubation data
E9: =STATS!J10 -> NIS | F9: =STATS!K10 -> 42
E10: =STATS!J11 -> RD | F10: =STATS!K11 -> 22
E11: =STATS!J12 -> ROV | F11: =STATS!K12 -> 22
E12: =STATS!J13 -> SCUBA | F12: =STATS!K13 -> 30
E13: =STATS!J14 -> SEAICE | F13: =STATS!K14 -> 2
E14: =STATS!J15 -> ST | F14: =STATS!K15 -> 2
E15: =STATS!J16 -> VV | F15: =STATS!K16 -> 7
F17: =SUM(F1:F15) -> 174

Sheet STATS
A1: Time Deployments | B1: =SUM(C:C) -> #REF! | E1: Number of Events | F1: =COUNTA(Events!B:B) -> 178 | H1: Number of Events per gear | J1: Number of Events per gear
A2: =Events!H2 -> 0.38680556 | B2: =Events!I2 -> 0.39375 | C2: =B2-A2 -> 0.0069444444 | E2: Number of Samples | F2: =COUNTA(Samples!B:B) -> 3952 | H2: AT | I2: 1 | J2: DR | K2: =COUNTIF(H:H, J2) -> 5
A3: =Events!H3 -> 0.40972222 | B3: =Events!I3 -> 0.4375 | C3: =B3-A3 -> 0.027777778 | H3: AT | I3: 2 | J3: AT | K3: =COUNTIF(H:H, J3) -> 5
A4: =Events!H4 -> 0.64583333 | B4: =Events!I4 -> 0.66666667 | C4: =B4-A4 -> 0.020833333 | H4: AT | I4: 3 | J4: BATHY | K4: =COUNTIF(H:H, J4) -> 0
A5: =Events!H5 -> 0.67013889 | B5: =Events!I5 -> 0.67708333 | C5: =B5-A5 -> 0.0069444444 | H5: AT | I5: 4 | J5: CTD | K5: =COUNTIF(H:H, J5) -> 13
A6: =Events!H6 -> 0.75 | B6: =Events!I6 -> 0.77083333 | C6: =B6-A6 -> 0.020833333 | H6: AT | I6: 5 | J6: CYANO | K6: =COUNTIF(H:H, J6) -> 5
A7: =Events!H7 -> 0.4375 | B7: =Events!I7 -> 0.45833333 | C7: =B7-A7 -> 0.020833333 | H7: CTD | I7: 1 | J7: DRM | K7: =COUNTIF(H:H, J7) -> 11
A8: =Events!H8 -> 0.6875 | B8: =Events!I8 -> 0.70833333 | C8: =B8-A8 -> 0.020833333 | H8: CTD | I8: 2 | J8: ICE | K8: =COUNTIF(H:H, J8) -> 0
A9: =Events!H9 -> 0.48958333 | B9: =Events!I9 -> 0 | C9: =B9-A9 -> -0.48958333 | H9: CTD | I9: 3 | J9: ITD | K9: =COUNTIF(H:H, J9) -> 3
A10: =Events!H10 -> 0.39583333 | B10: =Events!I10 -> 0.45833333 | C10: =B10-A10 -> 0.0625 | H10: CTD | I10: 4 | J10: NIS | K10: =COUNTIF(H:H, J10) -> 42
A11: =Events!H11 -> 0.42361111 | B11: =Events!I11 -> 0 | C11: =B11-A11 -> -0.42361111 | H11: CTD | I11: 5 | J11: RD | K11: =COUNTIF(H:H, J11) -> 22
A12: =Events!H12 -> 0.72916667 | B12: =Events!I12 -> 0.73958333 | C12: =B12-A12 -> 0.010416667 | H12: CTD | I12: 6 | J12: ROV | K12: =COUNTIF(H:H, J12) -> 22
A13: =Events!H13 -> 0.39583333 | B13: =Events!I13 -> 0.40277778 | C13: =B13-A13 -> 0.0069444444 | H13: CTD | I13: 7 | J13: SCUBA | K13: =COUNTIF(H:H, J13) -> 30
A14: =Events!H14 -> 0.51458333 | B14: =Events!I14 -> 0.52708333 | C14: =B14-A14 -> 0.0125 | H14: CTD | I14: 8 | J14: SEAICE | K14: =COUNTIF(H:H, J14) -> 2
... A17: =Events!H17 -> 0.43055556 | B17: =Events!I17 -> 0.4375 | C17: =B17-A17 -> 0.0069444444 | H17: CTD | I17: 11 | J17: ZZ | K17: =COUNTIF(H:H, J17) -> 1
A18: =Events!H18 -> 0.47152778 | B18: =Events!I18 -> 0.5 | C18: =B18-A18 -> 0.028472222 | H18: CTD | I18: 13
A19: =Events!H19 -> 0.64652778 | B19: =Events!I19 -> 0.70208333 | C19: =B19-A19 -> 0.055555556 | H19: CTD | I19: 14
A20: =Events!H20 -> 0.68055556 | B20: =Events!I20 -> 0.69444444 | C20: =B20-A20 -> 0.013888889 | H20: CYANO | I20: 1
A21: =Events!H21 -> 0.70833333 | B21: =Events!I21 -> 0.73263889 | C21: =B21-A21 -> 0.024305556 | H21: CYANO | I21: 2
A22: =Events!H22 -> 0 | B22: =Events!I22 -> 0 | C22: =B22-A22 -> 0 | H22: CYANO | I22: 3
A23: =Events!H23 -> 0.48819444 | B23: =Events!I23 -> 0.51041667 | C23: =B23-A23 -> 0.022222222 | H23: CYANO | I23: 4
A24: =Events!H24 -> 0.52083333 | B24: =Events!I24 -> 0.53125 | C24: =B24-A24 -> 0.010416667 | H24: CYANO | I24: 5
A25: =Events!H25 -> 0.53125 | B25: =Events!I25 -> 0.54166667 | C25: =B25-A25 -> 0.010416667 | H25: DR | I25: 1
A26: =Events!H26 -> 0.38194444 | B26: =Events!I26 -> 0.38333333 | C26: =B26-A26 -> 0.0013888889 | H26: DR | I26: 2
A27: =Events!H27 -> 0.45833333 | B27: =Events!I27 -> 0.47222222 | C27: =B27-A27 -> 0.013888889 | H27: DR | I27: 3
A28: =Events!H28 -> 0.58333333 | B28: =Events!I28 -> 0.59027778 | C28: =B28-A28 -> 0.0069444444 | H28: DR | I28: 4
A29: =Events!H29 -> 0.60416667 | B29: =Events!I29 -> 0.61805556 | C29: =B29-A29 -> 0.013888889 | H29: DR | I29: 5
... A158: =Events!H158 -> 0.59375 | B158: =Events!I158 -> 0.625 | C158: =B158-A158 -> 0.03125 | H158: SCUBA | I158: 29
A159: =Events!H160 -> 0.625 | B159: =Events!I159 -> 0.59375 | C159: =B159-A159 -> -0.03125 | H159: SCUBA | I159: 30
A160: =Events!H161 -> 0 | B160: =Events!I160 -> 0.63888889 | C160: =B160-A160 -> 0.63888889 | H160: SEAICE | I160: 1
A161: =Events!H162 -> 0.59375 | B161: =Events!I161 -> 0.39583333 | C161: =B161-A161 -> -0.19791667 | H161: SEAICE | I161: 2
A162: =Events!H163 -> 0.48333333 | B162: =Events!I162 -> 0.61736111 | C162: =B162-A162 -> 0.13402778 | H162: ST | I162: 1
A163: =Events!H164 -> 0.37708333 | B163: =Events!I163 -> 0.5 | C163: =B163-A163 -> 0.12291667 | H163: ST | I163: 2
A164: =Events!H165 -> 0.75 | B164: =Events!I164 -> 0.40277778 | C164: =B164-A164 -> -0.34722222 | H164: VV | I164: 1
A165: =Events!H166 -> 0.59375 | B165: =Events!I165 -> 0.76388889 | C165: =B165-A165 -> 0.17013889 | H165: VV | I165: 2
A166: =Events!H167 -> 0.42708333 | B166: =Events!I166 -> 0.65625 | C166: =B166-A166 -> 0.22916667 | H166: VV | I166: 3
A167: =Events!H168 -> 0.39583333 | B167: =Events!I167 -> 0.44791667 | C167: =B167-A167 -> 0.052083333 | H167: VV | I167: 4
A168: =Events!H169 -> 0.72083333 | B168: =Events!I168 -> 0.41666667 | C168: =B168-A168 -> -0.30416667 | H168: VV | I168: 5
A169: =Events!H170 -> 0.60138889 | B169: =Events!#REF! -> #REF! | C169: =B169-A169 -> #REF! | H169: VV | I169: 6
A170: =Events!H171 -> 0.60138889 | B170: =Events!I170 -> 0.62847222 | C170: =B170-A170 -> 0.027083333 | H170: VV | I170: 7
...

Sheet Events
A1: parentEventID | B1: eventID | C1: eventDate | D1: Collector | E1: Collector | F1: Collector | G1: Collector | H1: Time start (UTC-3) | I1: Time end (UTC-3) | J1: Time start (UTC) | K1: Time end (UTC) | L1: Latitude start (degree) | M1: Latitude start (decimal minutes) | N1: Longitude start (degree) | O1: Longitude start (decimal minutes) | P1: Latitude end (degree) | Q1: Latitude end (decimal minutes) | R1: Longitude end (degree) | S1: Longitude end (decimal minutes) | T1: Latitude start | U1: Longitude start | V1: Latitude end | W1: Longitude end | X1: Station Name | Y1: Minimum depth (m) | Z1: Maximum depth(m) | AA1: Max Altitude (m) | AB1: Bottom Depth (m) | AC1: Habitat | AD1: Sampling protocol | AE1: Gear Type | AF1: Event Remarks
A2: TANGO_1 Expedition | B2: DR_1 | C2: 44976 | D2: Bruno Danis | H2: 0.38680556 | I2: 0.39375 | L2: 66 | M2: 0.016 | N2: 65 | O2: 46.643 | T2: =-(L2+M2/60) -> -66.000267 | U2: =-(N2+O2/60) -> -65.777383 | V2: =-(P2+Q2/60) -> 0 | W2: =-(R2+S2/60) -> 0 | X2: Dodman Island | AA2: 500 | AE2: Mavic 2 PRO | AF2: Scouting, 500m alt
A3: TANGO_1 Expedition | B3: ROV_1 | C3: 44976 | D3: Lea Katz | H3: 0.40972222 | I3: 0.4375 | L3: 66 | M3: 0.016 | N3: 65 | O3: 46.643 | T3: =-(L3+M3/60) -> -66.000267 | U3: =-(N3+O3/60) -> -65.777383 | V3: =-(P3+Q3/60) -> 0 | W3: =-(R3+S3/60) -> 0 | X3: Dodman Island | Y3: 0 | Z3: 12 | AE3: BlueROV | AF3: 1 big quadrat
A4: TANGO_1 Expedition | B4: ROV_2 | C4: 44976 | D4: Lea Katz | H4: 0.64583333 | I4: 0.66666667 | L4: 66 | M4: 0.016 | N4: 65 | O4: 46.643 | T4: =-(L4+M4/60) -> -66.000267 | U4: =-(N4+O4/60) -> -65.777383 | V4: =-(P4+Q4/60) -> 0 | W4: =-(R4+S4/60) -> 0 | X4: Dodman Island | Y4: 0 | Z4: 12 | AE4: BlueROV | AF4: 1 quadrat + 1 transect
A5: TANGO_1 Expedition | B5: ROV_3 | C5: 44976 | D5: Lea Katz | H5: 0.67013889 | I5: 0.67708333 | L5: 66 | M5: 0.016 | N5: 65 | O5: 46.643 | T5: =-(L5+M5/60) -> -66.000267 | U5: =-(N5+O5/60) -> -65.777383 | V5: =-(P5+Q5/60) -> 0 | W5: =-(R5+S5/60) -> 0 | X5: Dodman Island | Y5: 0 | Z5: 12 | AE5: BlueROV | AF5: Transect tests
A6: TANGO_1 Expedition | B6: CTD_1 | C6: 44976 | D6: Axelle Brusselman | H6: 0.75 | I6: 0.77083333 | L6: 66 | M6: 0.016 | N6: 65 | O6: 46.643 | T6: =-(L6+M6/60) -> -66.000267 | U6: =-(N6+O6/60) -> -65.777383 | V6: =-(P6+Q6/60) -> 0 | W6: =-(R6+S6/60) -> 0 | X6: Dodman Island | Y6: 0 | Z6: 0 | AE6: STAR_ODDI DST CTD
A7: TANGO_1 Expedition | B7: RD_1 | C7: 44976 | D7: Henri Robert | E7: Camille Moreau | H7: 0.4375 | I7: 0.45833333 | L7: 66 | M7: 0.159 | N7: 65 | O7: 46.437 | P7: 66 | Q7: 0.23 | R7: 65 | S7: 46.613 | T7: =-(L7+M7/60) -> -66.00265 | U7: =-(N7+O7/60) -> -65.77395 | V7: =-(P7+Q7/60) -> -66.003833 | W7: =-(R7+S7/60) -> -65.776883 | X7: Dodman Island | Y7: 18 | Z7: 22
A8: TANGO_1 Expedition | B8: RD_2 | C8: 44976 | D8: Henri Robert | E8: Camille Moreau | H8: 0.6875 | I8: 0.70833333 | L8: 66 | M8: 0.14 | N8: 65 | O8: 46.52 | P8: 66 | Q8: 0.18 | R8: 65 | S8: 46.65 | T8: =-(L8+M8/60) -> -66.002333 | U8: =-(N8+O8/60) -> -65.775333 | V8: =-(P8+Q8/60) -> -66.003 | W8: =-(R8+S8/60) -> -65.7775 | X8: Dodman Island | Y8: 18 | Z8: 22
A9: TANGO_1 Expedition | B9: ST_1 | C9: 44976 | D9: Bruno Delille | E9: Axelle Brusselman | H9: 0.48958333 | T9: -65.98843 | U9: -65.787609 | V9: =-(P9+Q9/60) -> 0 | W9: =-(R9+S9/60) -> 0 | X9: Dodman Island | Y9: 18 | AF9: Deployment
A10: TANGO_1 Expedition | B10: ZZ_1 | C10: 44977 | H10: 0.39583333 | I10: 0.45833333 | L10: 66 | M10: 0.016 | N10: 65 | O10: 46.643 | T10: =-(L10+M10/60) -> -66.000267 | U10: =-(N10+O10/60) -> -65.777383 | V10: =-(P10+Q10/60) -> 0 | W10: =-(R10+S10/60) -> 0 | X10: Dodman Island | Y10: 0 | AE10: Bombard C4 | AF10: Scouting
A11: TANGO_1 Expedition | B11: AT_1 | C11: 44977 | D11: Henri Robert | H11: 0.42361111 | L11: 66 | M11: 0.083 | N11: 65 | O11: 47.249 | T11: =-(L11+M11/60) -> -66.001383 | U11: =-(N11+O11/60) -> -65.787483 | V11: =-(P11+Q11/60) -> 0 | W11: =-(R11+S11/60) -> 0 | X11: Dodman Island | Y11: 21 | AF11: Deployment
A12: TANGO_1 Expedition | B12: RD_3 | C12: 44977 | D12: Henri Robert | H12: 0.72916667 | I12: 0.73958333 | L12: 66 | M12: 0.046 | N12: 65 | O12: 47.22 | P12: 65 | Q12: 59.947 | R12: 65 | S12: 47.171 | T12: =-(L12+M12/60) -> -66.000767 | U12: =-(N12+O12/60) -> -65.787 | V12: =-(P12+Q12/60) -> -65.999117 | W12: =-(R12+S12/60) -> -65.786183 | X12: Dodman Island | Y12: 18
A13: TANGO_1 Expedition | B13: SCUBA_1 | C13: 44977 | D13: Francesca Pasotti | E13: Camille Moreau | H13: 0.39583333 | I13: 0.40277778 | L13: 66 | M13: 59.948 | N13: 65 | O13: 47.391 | T13: =-(L13+M13/60) -> -66.999133 | U13: =-(N13+O13/60) -> -65.78985 | V13: =-(P13+Q13/60) -> 0 | W13: =-(R13+S13/60) -> 0 | X13: Dodman Island | AE13: SCUBA | AF13: Glove Leak FP
A14: TANGO_1 Expedition | B14: SCUBA_2 | C14: 44977 | D14: Lea Katz | E14: Martin Dogniez | H14: 0.51458333 | I14: 0.52708333 | L14: 66 | M14: 0.016 | N14: 65 | O14: 46.643 | T14: =-(L14+M14/60) -> -66.000267 | U14: =-(N14+O14/60) -> -65.777383 | V14: =-(P14+Q14/60) -> 0 | W14: =-(R14+S14/60) -> 0 | X14: Dodman Island | Y14: 13 | AE14: SCUBA | AF14: Sterechinus sampling
A15: TANGO_1 Expedition | B15: SCUBA_3 | C15: 44977 | D15: Francesca Pasotti | E15: Martin Dogniez | H15: 0.60694444 | I15: 0.61805556 | L15: 66 | M15: 0.016 | N15: 65 | O15: 46.643 | T15: =-(L15+M15/60) -> -66.000267 | U15: =-(N15+O15/60) -> -65.777383 | V15: =-(P15+Q15/60) -> 0 | W15: =-(R15+S15/60) -> 0 | X15: Dodman Island | Y15: 12 | AE15: SCUBA | AF15: Glove Leak FP + core dysfunction
A16: TANGO_1 Expedition | B16: CTD_2 | C16: 44977 | D16: Bruno Delille | E16: Axelle Brusselman | H16: 0.35069444 | I16: 0.375 | L16: 66 | M16: 0.016 | N16: 65 | O16: 46.643 | T16: =-(L16+M16/60) -> -66.000267 | U16: =-(N16+O16/60) -> -65.777383 | V16: =-(P16+Q16/60) -> 0 | W16: =-(R16+S16/60) -> 0 | X16: Dodman Island | Y16: 0 | AE16: STAR_ODDI DST CTD | AF16: Test
A17: TANGO_1 Expedition | B17: CTD_3 | C17: 44977 | D17: Bruno Delille | E17: Axelle Brusselman | H17: 0.43055556 | I17: 0.4375 | L17: 66 | M17: 0.016 | N17: 65 | O17: 46.643 | T17: =-(L17+M17/60) -> -66.000267 | U17: =-(N17+O17/60) -> -65.777383 | V17: =-(P17+Q17/60) -> 0 | W17: =-(R17+S17/60) -> 0 | X17: Dodman Island | Y17: 0 | AE17: STAR_ODDI DST CTD | AF17: Test
A18: TANGO_1 Expedition | B18: CTD_4 | C18: 44977 | D18: Bruno Delille | E18: Axelle Brusselman | H18: 0.47152778 | I18: 0.5 | L18: 66 | M18: 0.016 | N18: 65 | O18: 46.643 | T18: =-(L18+M18/60) -> -66.000267 | U18: =-(N18+O18/60) -> -65.777383 | V18: =-(P18+Q18/60) -> 0 | W18: =-(R18+S18/60) -> 0 | X18: Dodman Island | Y18: 0 | AE18: STAR_ODDI DST CTD
A19: TANGO_1 Expedition | B19: ROV_4 | C19: 44977 | D19: Lea Katz | E19: Henri Robert | H19: 0.64652778 | I19: 0.70208333 | L19: 66 | M19: 0.016 | N19: 65 | O19: 46.643 | T19: =-(L19+M19/60) -> -66.000267 | U19: =-(N19+O19/60) -> -65.777383 | V19: =-(P19+Q19/60) -> 0 | W19: =-(R19+S19/60) -> 0 | X19: Dodman Island | Y19: 0 | Z19: 12 | AE19: BlueROV | AF19: 3 quadrats
A20: TANGO_1 Expedition | B20: DRM_1 | C20: 44977 | D20: Bruno Danis | H20: 0.68055556 | I20: 0.69444444 | L20: 66 | M20: 0.016 | N20: 65 | O20: 46.643 | T20: =-(L20+M20/60) -> -66.000267 | U20: =-(N20+O20/60) -> -65.777383 | V20: =-(P20+Q20/60) -> 0 | W20: =-(R20+S20/60) -> 0 | X20: Dodman Island | AA20: 75 | AC20: Aerial | AE20: Mavic 2 PRO | AF20: DroneDeploy Photogrammetry
A21: TANGO_1 Expedition | B21: DRM_2 | C21: 44977 | D21: Bruno Danis | H21: 0.70833333 | I21: 0.73263889 | L21: 66 | M21: 0.016 | N21: 65 | O21: 46.643 | T21: =-(L21+M21/60) -> -66.000267 | U21: =-(N21+O21/60) -> -65.777383 | V21: =-(P21+Q21/60) -> 0 | W21: =-(R21+S21/60) -> 0 | X21: Dodman Island | AA21: 75 | AC21: Aerial | AE21: Mavic 2 PRO | AF21: DroneDeploy Photogrammetry
A22: TANGO_1 Expedition | B22: ITD_1 | C22: 44977 | D22: Camille Moreau | T22: =-(L22+M22/60) -> 0 | U22: =-(N22+O22/60) -> 0 | V22: =-(P22+Q22/60) -> 0 | W22: =-(R22+S22/60) -> 0 | X22: Dodman Island | Y22: 0 | Z22: 0 | AF22: Sample for Guillaume Schwob
A23: TANGO_1 Expedition | B23: NIS_1 | C23: 44977 | D23: Bruno Delille | E23: Axelle Brusselman | H23: 0.48819444 | I23: 0.51041667 | L23: 66 | M23: 0.016 | N23: 65 | O23: 46.643 | T23: =-(L23+M23/60) -> -66.000267 | U23: =-(N23+O23/60) -> -65.777383 | V23: =-(P23+Q23/60) -> 0 | W23: =-(R23+S23/60) -> 0 | X23: Dodman Island | Z23: 12 | AE23: NISKIN 3L
A24: TANGO_1 Expedition | B24: NIS_2 | C24: 44977 | D24: Bruno Delille | E24: Axelle Brusselman | H24: 0.52083333 | I24: 0.53125 | L24: 66 | M24: 0.016 | N24: 65 | O24: 46.643 | T24: =-(L24+M24/60) -> -66.000267 | U24: =-(N24+O24/60) -> -65.777383 | V24: =-(P24+Q24/60) -> 0 | W24: =-(R24+S24/60) -> 0 | X24: Dodman Island | Z24: 6 | AE24: NISKIN 3L
A25: TANGO_1 Expedition | B25: NIS_3 | C25: 44977 | D25: Bruno Delille | E25: Axelle Brusselman | H25: 0.53125 | I25: 0.54166667 | L25: 66 | M25: 0.016 | N25: 65 | O25: 46.643 | T25: =-(L25+M25/60) -> -66.000267 | U25: =-(N25+O25/60) -> -65.777383 | V25: =-(P25+Q25/60) -> 0 | W25: =-(R25+S25/60) -> 0 | X25: Dodman Island | Z25: 0 | AE25: NISKIN 3L
A26: TANGO_1 Expedition | B26: NIS_4 | C26: 44978 | D26: Bruno Delille | E26: Axelle Brusselman | H26: 0.38194444 | I26: 0.38333333 | L26: 66 | M26: 0.016 | N26: 65 | O26: 46.643 | T26: =-(L26+M26/60) -> -66.000267 | U26: =-(N26+O26/60) -> -65.777383 | V26: =-(P26+Q26/60) -> 0 | W26: =-(R26+S26/60) -> 0 | X26: Dodman Island | AE26: NISKIN 3L
A27: TANGO_1 Expedition | B27: RD_4 | C27: 44978 | D27: Henri Robert | H27: 0.45833333 | I27: 0.47222222 | L27: 66 | M27: 0.253 | N27: 65 | O27: 46.212 | P27: 66 | Q27: 0.0209 | R27: 65 | S27: 46.149 | T27: =-(L27+M27/60) -> -66.004217 | U27: =-(N27+O27/60) -> -65.7702 | V27: =-(R27+S27/60) -> -65.76915 | W27: =-(R27+S27/60) -> -65.76915 | X27: Dodman Island | Y27: 21.6 | Z27: 15
A28: TANGO_1 Expedition | B28: NIS_19 | C28: 44978 | D28: Camille Moreau | E28: Bruno Danis | H28: 0.58333333 | I28: 0.59027778 | L28: 66 | M28: 0.0295 | N28: 65 | O28: 46.747 | T28: =-(L28+M28/60) -> -66.000492 | U28: =-(N28+O28/60) -> -65.779117 | V28: =-(R28+S28/60) -> 0 | W28: =-(R28+S28/60) -> 0 | X28: Dodman Island | Y28: 15 | Z28: 15 | AE28: NISKIN 3L
A29: TANGO_1 Expedition | B29: RD_5 | C29: 44978 | D29: Henri Robert | H29: 0.60416667 | I29: 0.61805556 | L29: 66 | M29: 0.289 | N29: 65 | O29: 46.66 | P29: 66 | Q29: 0.0221 | R29: 66 | S29: 46.686 | T29: =-(L29+M29/60) -> -66.004817 | U29: =-(N29+O29/60) -> -65.777667 | V29: =-(R29+S29/60) -> -66.7781 | W29: =-(R29+S29/60) -> -66.7781 | X29: Dodman Island | Y29: 23 | Z29: 20
A30: TANGO_1 Expedition | B30: AT_1 | C30: 44978 | D30: Henri Robert | I30: 0.6875 | P30: 66 | Q30: 0.0083 | R30: 66 | S30: 47.249 | T30: =-(L30+M30/60) -> 0 | U30: =-(N30+O30/60) -> 0 | V30: =-(R30+S30/60) -> -66.787483 | W30: =-(R30+S30/60) -> -66.787483 | X30: Dodman Island | Z30: 21 | AF30: Retrieval
A31: TANGO_1 Expedition | B31: NIS_5 | C31: 44978 | D31: Bruno Delille | E31: Axelle Brusselman | H31: 0.72708333 | I31: 0.73055556 | L31: 65 | M31: 99.94 | N31: 65 | O31: 76.89 | T31: =-(L31+M31/60) -> -66.665667 | U31: =-(N31+O31/60) -> -66.2815 | V31: =-(P31+Q31/60) -> 0 | W31: =-(R31+S31/60) -> 0 | X31: Dodman Island | Y31: 0 | Z31: 0 | AE31: NISKIN 3L
A32: TANGO_1 Expedition | B32: NIS_6 | C32: 44978 | D32: Bruno Delille | E32: Axelle Brusselman | H32: 0.68333333 | I32: 0.68680556 | L32: 66 | M32: 0.087 | N32: 65 | O32: 78.95 | T32: =-(L32+M32/60) -> -66.00145 | U32: =-(N32+O32/60) -> -66.315833 | V32: =-(P32+Q32/60) -> 0 | W32: =-(R32+S32/60) -> 0 | X32: Dodman Island | Y32: 0 | Z32: 0 | AE32: NISKIN 3L
A33: TANGO_1 Expedition | B33: NIS_7 | C33: 44978 | D33: Bruno Delille | E33: Axelle Brusselman | H33: 0.69166667 | I33: 0.69513889 | L33: 66 | M33: 0.039 | N33: 65 | O33: 78.95 | T33: =-(L33+M33/60) -> -66.00065 | U33: =-(N33+O33/60) -> -66.315833 | V33: =-(P33+Q33/60) -> 0 | W33: =-(R33+S33/60) -> 0 | X33: Dodman Island | Y33: 0 | Z33: 0 | AE33: NISKIN 3L
A34: TANGO_1 Expedition | B34: NIS_8 | C34: 44978 | D34: Bruno Delille | E34: Axelle Brusselman | H34: 0.70069444 | I34: 0.70416667 | L34: 65 | M34: 99.97 | N34: 65 | O34: 78.95 | T34: =-(L34+M34/60) -> -66.666167 | U34: =-(N34+O34/60) -> -66.315833 | V34: =-(P34+Q34/60) -> 0 | W34: =-(R34+S34/60) -> 0 | X34: Dodman Island | Y34: 0 | Z34: 0 | AE34: NISKIN 3L
A35: TANGO_1 Expedition | B35: NIS_9 | C35: 44978 | D35: Bruno Delille | E35: Axelle Brusselman | H35: 0.70486111 | I35: 0.70833333 | L35: 65 | M35: 99.75 | N35: 65 | O35: 78.95 | T35: =-(L35+M35/60) -> -66.6625 | U35: =-(N35+O35/60) -> -66.315833 | V35: =-(P35+Q35/60) -> 0 | W35: =-(R35+S35/60) -> 0 | X35: Dodman Island | Y35: 0 | Z35: 0 | AE35: NISKIN 3L
A36: TANGO_1 Expedition | B36: NIS_10 | C36: 44978 | D36: Bruno Delille | E36: Axelle Brusselman | H36: 0.71041667 | I36: 0.71388889 | L36: 65 | M36: 99.65 | N36: 65 | O36: 78.95 | T36: =-(L36+M36/60) -> -66.660833 | U36: =-(N36+O36/60) -> -66.315833 | V36: =-(P36+Q36/60) -> 0 | W36: =-(R36+S36/60) -> 0 | X36: Dodman Island | Y36: 0 | Z36: 0 | AE36: NISKIN 3L
A37: TANGO_1 Expedition | B37: NIS_11 | C37: 44978 | D37: Bruno Delille | E37: Axelle Brusselman | H37: 0.71666667 | I37: 0.72013889 | L37: 65 | M37: 99.68 | N37: 65 | O37: 78.53 | T37: =-(L37+M37/60) -> -66.661333 | U37: =-(N37+O37/60) -> -66.308833 | V37: =-(P37+Q37/60) -> 0 | W37: =-(R37+S37/60) -> 0 | X37: Dodman Island | Y37: 0 | Z37: 0 | AE37: NISKIN 3L
A38: TANGO_1 Expedition | B38: NIS_12 | C38: 44978 | D38: Bruno Delille | E38: Axelle Brusselman | H38: 0.60486111 | I38: 0.60833333 | L38: 66 | M38: 1.31 | N38: 65 | O38: 78.95 | T38: =-(L38+M38/60) -> -66.021833 | U38: =-(N38+O38/60) -> -66.315833 | V38: =-(P38+Q38/60) -> 0 | W38: =-(R38+S38/60) -> 0 | X38: Dodman Island | Y38: 0 | Z38: 0 | AE38: NISKIN 3L
A39: TANGO_1 Expedition | B39: NIS_13 | C39: 44978 | D39: Bruno Delille | E39: Axelle Brusselman | H39: 0.61458333 | I39: 0.61805556 | L39: 66 | M39: 1.17 | N39: 65 | O39: 77.81 | T39: =-(L39+M39/60) -> -66.0195 | U39: =-(N39+O39/60) -> -66.296833 | V39: =-(P39+Q39/60) -> 0 | W39: =-(R39+S39/60) -> 0 | X39: Dodman Island | Y39: 0 | Z39: 0 | AE39: NISKIN 3L
A40: TANGO_1 Expedition | B40: NIS_14 | C40: 44978 | D40: Bruno Delille | E40: Axelle Brusselman | H40: 0.62013889 | I40: 0.62361111 | L40: 66 | M40: 1.04 | N40: 65 | O40: 76.72 | T40: =-(L40+M40/60) -> -66.017333 | U40: =-(N40+O40/60) -> -66.278667 | V40: =-(P40+Q40/60) -> 0 | W40: =-(R40+S40/60) -> 0 | X40: Dodman Island | Y40: 0 | Z40: 0 | AE40: NISKIN 3L
...

Sheet Samples
A1: parentSampleID | B1: sampleID | C1: eventID | D1: Sample Type | E1: Parameter | F1: scientificName | G1: individualCount | H1: identifiedBy1 | I1: identifiedBy2 | J1: identifiedBy3 | L1: preserved in | M1: container | N1: Remark | O1: recordedBy1 | P1: recordedBy2 | Q1: Project | R1: scientificNameAuthorship | S1: identificationQualifier | T1: kingdom | U1: phylum | V1: class | W1: order | X1: family | Y1: genus | Z1: species | AA1: institutionCode | AB1: occurrenceRemarks
B2: 1 | C2: DR_1 | D2: Media_file | E2: Aerial Imagery | H2: Bruno Danis | M2: image files | O2: Bruno Danis | P2: Henri Robert
B3: 2 | C3: ROV_1 | D3: Media_folder | E3: Mapping Quadrat | M3: Folder | N3: Pool 4 | O3: Bruno Danis | P3: Henri Robert
B4: 3 | C4: ROV_2 | D4: Media_folder | E4: Mapping Quadrat | H4: Bruno Danis | I4: Lea Katz | M4: Folder | N4: Pool 4 | O4: Bruno Danis | P4: Henri Robert
B5: 4 | C5: ROV_2 | D5: Media_folder | E5: Mapping Transect | H5: Bruno Danis | I5: Lea Katz | M5: Folder | N5: Pool 4 | O5: Bruno Danis | P5: Henri Robert
B6: 5 | C6: ROV_3 | D6: Media_folder | E6: Mapping Transect | H6: Bruno Danis | I6: Lea Katz | M6: Folder | N6: Pool 4 | O6: Bruno Danis | P6: Henri Robert
B7: 6 | C7: CTD_1 | D7: Media_file | E7: Conductivity - Salinity - Depth | O7: Bruno Danis | P7: Henri Robert
B8: 7 | C8: RD_1 | D8: Individual | E8: Biodiversity | F8: Invertebrates | G8: 4 | H8: Henri Robert | I8: Camille Moreau | L8: EtOH 70 | M8: Kautex 500 ml | O8: Bruno Danis | P8: Henri Robert
B9: 8 | C9: RD_1 | D9: Individual | E9: Biodiversity | F9: Invertebrates | G9: 500 | H9: Henri Robert | I9: Camille Moreau | L9: EtOH | M9: Kautex 100 ml | O9: Bruno Danis | P9: Henri Robert
B10: 9 | C10: RD_1 | D10: Individual | E10: Biodiversity | F10: Invertebrates | G10: 15 | H10: Henri Robert | I10: Camille Moreau | L10: EtOH | M10: Kautex 100 ml | O10: Bruno Danis | P10: Henri Robert
B11: 10 | C11: RD_1 | D11: Individual | E11: Biodiversity | F11: Invertebrates | G11: 250 | H11: Henri Robert | I11: Camille Moreau | L11: EtOH | M11: Kautex 100 ml | O11: Bruno Danis | P11: Henri Robert
B12: 11 | C12: RD_1 | D12: Individual | E12: Biodiversity | F12: Invertebrates | G12: 1000 | H12: Henri Robert | I12: Camille Moreau | L12: EtOH | M12: Kautex 100 ml | O12: Bruno Danis | P12: Henri Robert
B13: 12 | C13: RD_2 | D13: Individual | E13: Biodiversity | F13: Invertebrates | G13: 2753 | H13: Henri Robert | L13: EtOH | M13: Brown 2 l jar | O13: Bruno Danis | P13: Henri Robert
B14: 13 | C14: RD_2 | D14: Individual | E14: Biodiversity | F14: Sterechinus neumayeri | G14: 2 | H14: Henri Robert | L14: EtOH | M14: Kautex 500 ml | O14: Bruno Danis | P14: Henri Robert
B15: 14 | C15: RD_2 | D15: Individual | E15: Biodiversity | F15: Parborlasia corrugatus | G15: 1 | H15: Henri Robert | L15: EtOH | M15: Kautex 100 ml | O15: Bruno Danis | P15: Henri Robert
B16: 15 | C16: RD_2 | D16: Individual | E16: Biodiversity | F16: cfr Bovalia gigantea | G16: 1 | H16: Henri Robert | L16: EtOH | M16: Vial 5 ml | O16: Bruno Danis | P16: Henri Robert
B17: 16 | C17: RD_2 | D17: Individual | E17: Biodiversity | F17: Polychaeta | G17: 3 | H17: Henri Robert | L17: EtOH | M17: Falcon 50 ml | O17: Bruno Danis | P17: Henri Robert
B18: 17 | C18: RD_3 | D18: Individual | E18: Biodiversity | F18: Amphipoda | G18: 400 | H18: Henri Robert | L18: EtOH | M18: Kautex 500 ml | O18: Bruno Danis | P18: Henri Robert
B19: 18 | C19: SCUBA_15 | D19: Tissue | E19: Microbiology | F19: Porifera | H19: Bruno Danis | L19: Glycerol | M19: Eppendorf 1.5 ml | N19: Microbiology for Isabelle George, in Bag Manon O3 | O19: Bruno Danis | P19: Henri Robert
B20: 19 | C20: DRM_1 | D20: Media_file | E20: Aerial Mapping | H20: Bruno Danis | M20: image files | N20: DroneDeploy, for Photogrametry | O20: Bruno Danis | P20: Henri Robert
B21: 20 | C21: DRM_2 | D21: Media_file | E21: Aerial Mapping | H21: Bruno Danis | M21: image files | N21: DroneDeploy, for Photogrametry | O21: Bruno Danis | P21: Henri Robert
B22: 24 | C22: ZZ_1 | D22: Individual | E22: Biodiversity | F22: Tunicata | G22: 1 | H22: Camille Moreau | I22: Bruno Danis | L22: EtOH | M22: Kautex 500 ml | N22: Opportunistic | O22: Bruno Danis | P22: Henri Robert
B23: 25 | C23: SCUBA_2 | D23: Individual | E23: Symbiotes analysis | F23: Sterechinus neumayeri | G23: 1 | H23: Martin Dogniez | O23: Bruno Danis | P23: Henri Robert
B24: 25 | C24: SCUBA_2 | D24: Individual | F24: Sterechinus neumayeri | H24: Camille Moreau | I24: Bruno Danis | J24: Lea Katz | L24: Dissected
B25: 26 | C25: SCUBA_2 | D25: Individual | E25: Symbiotes analysis | F25: Sterechinus neumayeri | G25: 1 | H25: Martin Dogniez | O25: Bruno Danis | P25: Henri Robert
B26: 26 | C26: SCUBA_2 | D26: Individual | F26: Sterechinus neumayeri | H26: Camille Moreau | I26: Bruno Danis | J26: Lea Katz
B27: 27 | C27: SCUBA_2 | D27: Individual | E27: Symbiotes analysis | F27: Sterechinus neumayeri | G27: 1 | H27: Martin Dogniez | O27: Bruno Danis | P27: Henri Robert
B28: 27 | C28: SCUBA_2 | D28: Individual | F28: Sterechinus neumayeri | H28: Camille Moreau | I28: Bruno Danis | J28: Lea Katz
B29: 28 | C29: SCUBA_2 | D29: Individual | E29: Symbiotes analysis | F29: Sterechinus neumayeri | G29: 1 | H29: Martin Dogniez | O29: Bruno Danis | P29: Henri Robert
B30: 28 | C30: SCUBA_2 | D30: Individual | F30: Sterechinus neumayeri | H30: Camille Moreau | I30: Bruno Danis | J30: Lea Katz
B31: 29 | C31: SCUBA_2 | D31: Individual | E31: Symbiotes analysis | F31: Sterechinus neumayeri | G31: 1 | H31: Martin Dogniez | O31: Bruno Danis | P31: Henri Robert
B32: 29 | C32: SCUBA_2 | D32: Individual | F32: Sterechinus neumayeri | H32: Camille Moreau | I32: Bruno Danis | J32: Lea Katz
B33: 30 | C33: SCUBA_2 | D33: Individual | E33: Symbiotes analysis | F33: Sterechinus neumayeri | G33: 1 | H33: Martin Dogniez | O33: Bruno Danis | P33: Henri Robert
B34: 30 | C34: SCUBA_2 | D34: Individual | F34: Sterechinus neumayeri | H34: Camille Moreau | I34: Bruno Danis | J34: Lea Katz
B35: 31 | C35: SCUBA_2 | D35: Individual | E35: Symbiotes analysis | F35: Sterechinus neumayeri | G35: 1 | H35: Martin Dogniez | O35: Bruno Danis | P35: Henri Robert
B36: 31 | C36: SCUBA_2 | D36: Individual | F36: Sterechinus neumayeri | H36: Camille Moreau | I36: Bruno Danis | J36: Lea Katz
B37: 32 | C37: SCUBA_2 | D37: Individual | E37: Symbiotes analysis | F37: Sterechinus neumayeri | G37: 1 | H37: Martin Dogniez | O37: Bruno Danis | P37: Henri Robert
B38: 32 | C38: SCUBA_2 | D38: Individual | F38: Sterechinus neumayeri | H38: Camille Moreau | I38: Bruno Danis | J38: Lea Katz
B39: 33 | C39: SCUBA_2 | D39: Individual | E39: Symbiotes analysis | F39: Sterechinus neumayeri | G39: 1 | H39: Martin Dogniez | O39: Bruno Danis | P39: Henri Robert
B40: 33 | C40: SCUBA_2 | D40: Individual | F40: Sterechinus neumayeri | H40: Camille Moreau | I40: Bruno Danis | J40: Lea Katz
...

Sheet Incubations
A1: parentSampleID | B1: sampleID | C1: eventID | D1: Sample Type | E1: Parameter | F1: scientificName | G1: individualCount | H1: identifiedBy1 | I1: identifiedBy2 | J1: identifiedBy3 | K1: preserved in | L1: container | M1: Remark | N1: recordedBy1 | O1: recordedBy2 | P1: Project | Q1: scientificNameAuthorship | R1: identificationQualifier | S1: kingdom | T1: phylum | U1: class | V1: order | W1: family | X1: genus | Y1: species | Z1: institutionCode | AA1: occurrenceRemarks
B2: 200 | C2: SCUBA_4 | D2: Sediments | H2: Francesca Pasotti | I2: Marius Buydens | M2: Incubation Cores | N2: Bruno Danis | O2: Henri Robert
A3: 200 | B3: XXX | C3: SCUBA_4 | D3: Media_folder | E3: DIC | K3: xls file
A4: 200 | B4: XXX | C4: SCUBA_4 | D4: Media_folder | E4: Nutrients | K4: xls file
A5: 200 | B5: XXX | C5: SCUBA_4 | D5: Media_folder | E5: DIC | K5: xls file
A6: 200 | B6: XXX | C6: SCUBA_4 | D6: Media_folder | E6: Nutrients | K6: xls file
A7: 200 | B7: XXX | C7: SCUBA_4 | D7: Media_folder | E7: DIC | K7: xls file
A8: 200 | B8: XXX | C8: SCUBA_4 | D8: Media_folder | E8: Nutrients | K8: xls file
A9: 200 | B9: XXX | C9: SCUBA_4 | D9: Media_folder | E9: DIC | K9: xls file
A10: 200 | B10: XXX | C10: SCUBA_4 | D10: Media_folder | E10: Nutrients | K10: xls file
A11: 200 | B11: XXX | C11: SCUBA_4 | D11: Media_folder | E11: DIC | K11: xls file
A12: 200 | B12: XXX | C12: SCUBA_4 | D12: Media_folder | E12: Nutrients | K12: xls file
A13: 200 | B13: XXX | C13: SCUBA_4 | D13: Media_folder | E13: DIC | K13: xls file
A14: 200 | B14: XXX | C14: SCUBA_4 | D14: Media_folder | E14: Nutrients | K14: xls file
... A16: 200 | B16: XXX | C16: SCUBA_4 | D16: Media_folder | E16: Nutrients | K16: xls file
A17: 200 | B17: XXX | C17: SCUBA_4 | D17: Seawater | E17: DIC | K17: HgCl2 | L17: Exetainer (20 ml)
A18: 200 | B18: XXX | C18: SCUBA_4 | D18: Seawater | E18: Alcalinity | K18: HgCl2 | L18: Exetainer (100 ml)
A19: 200 | B19: XXX | C19: SCUBA_4 | D19: Seawater | E19: Nutrients | K19: HgCl2 | L19: Scintillation vial (20 ml)
A20: 200 | B20: XXX | C20: SCUBA_4 | D20: Seawater | E20: N20, CH4 | K20: HgCl2 | L20: Exetainer (100 ml)
A21: 200 | B21: XXX | C21: SCUBA_4 | D21: Porewater | E21: DIC | K21: HgCl2 | L21: Exetainer (350µl)
A22: 200 | B22: XXX | C22: SCUBA_4 | D22: Porewater | E22: Nutrients | K22: Frozen (-20°) | L22: Eppendorf (1,5 ml)
A23: 200 | B23: XXX | C23: SCUBA_4 | D23: Seawater | E23: Alcalinity | K23: HgCl2 | L23: Exetainer (XX ml)
A24: 200 | B24: XXX | C24: SCUBA_4 | D24: Seawater | E24: N20, CH4 | K24: HgCl2 | L24: Exetainer (100 ml)
A25: 200 | B25: XXX | C25: SCUBA_4 | D25: Seawater | E25: Alcalinity | K25: HgCl2 | L25: Exetainer (100 ml)
A26: 200 | B26: XXX | C26: SCUBA_4 | D26: Seawater | E26: N20, CH4 | K26: HgCl2 | L26: Exetainer (100 ml)
A27: 200 | B27: XXX | C27: SCUBA_4 | D27: Biota | E27: Biodiversity (Macrofauna) | K27: Formaldehyde 8%
A28: 200 | C28: SCUBA_4 | D28: Seawater | E28: Backup SW sample | K28: Frozen (-20°) | L28: Plastic Vial 250 ml

Sheet Variables
A1: sampleType | B1: gearType
A2: 14C AMS dating | B2: 500 ml bottle
A3: AADI | B3: Active water sampler
A4: Acoustics recorder | B4: ADCP
A5: ADCP | B5: Algal Incubator
A6: aDNA | B6: ARGO
A7: Algae aggregates | B7: ASSIST
A8: AT/DIC/pH | B8: AUV
A9: Bacterial production | B9: Beam trawl
A10: Bio bulk | B10: Bongonet 180 um
A11: Biogenic silica | B11: Bongonet 64 um
A12: Brine | B12: Bottle 1L
... A76: Mesozooplankton ecotoxicology | B76: WP3 1000 um
A77: Mesozooplankton metagenomics
A78: Mesozooplankton taxonomy
A79: Mesozooplankton taxonomy
A80: Methylmercury
A81: Microalgal diversity
A82: Microbial abundance
A83: Microbial activity (RNA)
A84: Microbial diversity (DNA and RNA)
A85: Microzooplankton abundance
A86: Microzooplankton biomass
A87: Mixotrophy FISH
A88: Multicore
... A140: Water

Sheet Drop-down_menus
A1: sampleType | B1: basisOfRecord | C1: preparations | D1: person | E1: orcid | F1: institutionCode | G1: institutionID | H1: project
A2: gut | B2: MaterialSample | C2: Ethanol 100 | D2: Axelle Brusselman | F2: UGENT | G2: https://ror.org/00cv9y106 | H2: BENTHOS
A3: body | B3: MachineObservation | C3: Dried | D3: Annette Bombosch | E3: https://orcid.org/0000-0002-9037-7623 | F3: ULB | G3: https://ror.org/01r9htc13 | H3: BIOGEO
A4: limb | B4: observation | C4: Frozen (-20°C) | D4: Ben Wallis | E4: https://orcid.org/0000-0003-0502-8101 | F4: ULiege | G4: https://ror.org/00afp2z80 | H4: ICE
A5: media_file | C5: Ethanol 70 | D5: Bruno Danis | E5: https://orcid.org/0000-0002-0981-7442 | H5: INTERTIDAL
A6: sediment | C6: RNA Later | D6: Bruno Delille | E6: https://orcid.org/0000-0002-8971-8195 | H6: MEIO
A7: suspended particulate organic matter | C7: DNA buffer | D7: Camille Moreau | H7: PELAGIC
A8: swab | C8: Formaldehyde 8% | D8: Francesca Pasotti | E8: https://orcid.org/0000-0001-5748-602X | H8: ROV
A9: tissue | C9: Flash frozen (liquid N2) | D9: Henri Robert | H9: SONATINA
A10: observation | D10: Lea Katz | E10: https://orcid.org/0000-0002-9708-1761 | H10: SYMB
A11: digestive pellets | D11: Maria Amenabar | H11: TOP
A12: seawater | D12: Marius Buydens | H12: TROPHIC
A13: individual | D13: Martin Dogniez
A14: sea ice | D14: ALL
A15: filtrate
A16: media_folder

Sheet Abbreviations
A1: AT | B1: Amphipod Trap
A2: CTD | B2: Conductivity-Salinity-Temperature
A3: DR | B3: Drone
A4: DRM | B4: Drone Mapping
A5: ITD | B5: Intertidal
A6: NIS | B6: Niskin
A7: RD | B7: Rauschert Dredge
A8: ROV | B8: Remotely Operated Vehicle
A9: SCUBA | B9: Scuba Divers
A10: ST | B10: Sedimet Traps
A11: ZZ | B11: Zodiac Zip

Sheet LatLong_converter
A2: Coordinate conversion
A3: Degree Minutes Seconds
A4: Degrees
A5: Minutes
A6: Seconds
A7: Decimal degrees | B7: =B4+B5/60+B6/3600 -> 0
A8: Degree decimal minutes
A9: Degrees | B9: 66
A10: Decimal minutes | B10: 0.016
A11: Decimal degrees | B11: =B9+B10/60 -> 66.000267

Sheet SW_parameters
A1: Measurement parameter/name | B1: Project | C1: Gear | D1: Meas urement Unit | E1: Method responsible
A2: Sea Ice Thickness (cm)
A3: Sea Water pH (total scale)
A4: POC (ug/L)
A5: Sea Water Practical Salinity (1)
A6: Sea Water Conductivity (S/m)
A7: Sea Water Temp (C) | D7: °C
A8: Sediment TOC (mg/L) | D8: mg/L
